[2022-03-15 15:22:19,249] {taskinstance.py:1037} INFO - Dependencies all met for <TaskInstance: simple_dag.to_sql scheduled__2022-03-15T15:20:51.391365+00:00 [queued]>
[2022-03-15 15:22:19,259] {taskinstance.py:1037} INFO - Dependencies all met for <TaskInstance: simple_dag.to_sql scheduled__2022-03-15T15:20:51.391365+00:00 [queued]>
[2022-03-15 15:22:19,260] {taskinstance.py:1243} INFO - 
--------------------------------------------------------------------------------
[2022-03-15 15:22:19,260] {taskinstance.py:1244} INFO - Starting attempt 1 of 1
[2022-03-15 15:22:19,260] {taskinstance.py:1245} INFO - 
--------------------------------------------------------------------------------
[2022-03-15 15:22:19,270] {taskinstance.py:1264} INFO - Executing <Task(PythonOperator): to_sql> on 2022-03-15 15:20:51.391365+00:00
[2022-03-15 15:22:19,275] {standard_task_runner.py:52} INFO - Started process 28253 to run task
[2022-03-15 15:22:19,280] {standard_task_runner.py:76} INFO - Running: ['airflow', 'tasks', 'run', 'simple_dag', 'to_sql', 'scheduled__2022-03-15T15:20:51.391365+00:00', '--job-id', '343', '--raw', '--subdir', 'DAGS_FOLDER/simple_dag.py', '--cfg-path', '/var/folders/tl/ljh9dpdd2fnbgmc62qc2b49h0000gn/T/tmp897hegez', '--error-file', '/var/folders/tl/ljh9dpdd2fnbgmc62qc2b49h0000gn/T/tmpig_69d1t']
[2022-03-15 15:22:19,283] {standard_task_runner.py:77} INFO - Job 343: Subtask to_sql
[2022-03-15 15:22:19,340] {logging_mixin.py:109} INFO - Running <TaskInstance: simple_dag.to_sql scheduled__2022-03-15T15:20:51.391365+00:00 [running]> on host 1.0.0.0.0.0.0.0.0.0.0.0.0.0.0.0.0.0.0.0.0.0.0.0.0.0.0.0.0.0.0.0.ip6.arpa
[2022-03-15 15:22:19,389] {taskinstance.py:1429} INFO - Exporting the following env vars:
AIRFLOW_CTX_DAG_OWNER=airflow
AIRFLOW_CTX_DAG_ID=simple_dag
AIRFLOW_CTX_TASK_ID=to_sql
AIRFLOW_CTX_EXECUTION_DATE=2022-03-15T15:20:51.391365+00:00
AIRFLOW_CTX_DAG_RUN_ID=scheduled__2022-03-15T15:20:51.391365+00:00
[2022-03-15 15:22:20,241] {logging_mixin.py:109} INFO - Empty DataFrame
Columns: [id, title, servings, summary, diets, equipment, ingredients]
Index: []
[2022-03-15 15:22:20,253] {base_aws.py:190} INFO - Credentials retrieved from login
[2022-03-15 15:22:20,255] {base_aws.py:90} INFO - Retrieving region_name from Connection.extra_config['region_name']
[2022-03-15 15:22:20,696] {base_aws.py:190} INFO - Credentials retrieved from login
[2022-03-15 15:22:20,697] {base_aws.py:90} INFO - Retrieving region_name from Connection.extra_config['region_name']
[2022-03-15 15:22:21,246] {base_aws.py:190} INFO - Credentials retrieved from login
[2022-03-15 15:22:21,247] {base_aws.py:90} INFO - Retrieving region_name from Connection.extra_config['region_name']
[2022-03-15 15:22:22,064] {base_aws.py:190} INFO - Credentials retrieved from login
[2022-03-15 15:22:22,066] {base_aws.py:90} INFO - Retrieving region_name from Connection.extra_config['region_name']
[2022-03-15 15:22:22,474] {base_aws.py:190} INFO - Credentials retrieved from login
[2022-03-15 15:22:22,475] {base_aws.py:90} INFO - Retrieving region_name from Connection.extra_config['region_name']
[2022-03-15 15:22:22,918] {base_aws.py:190} INFO - Credentials retrieved from login
[2022-03-15 15:22:22,919] {base_aws.py:90} INFO - Retrieving region_name from Connection.extra_config['region_name']
[2022-03-15 15:22:23,365] {base_aws.py:190} INFO - Credentials retrieved from login
[2022-03-15 15:22:23,366] {base_aws.py:90} INFO - Retrieving region_name from Connection.extra_config['region_name']
[2022-03-15 15:22:23,777] {base_aws.py:190} INFO - Credentials retrieved from login
[2022-03-15 15:22:23,778] {base_aws.py:90} INFO - Retrieving region_name from Connection.extra_config['region_name']
[2022-03-15 15:22:24,352] {base_aws.py:190} INFO - Credentials retrieved from login
[2022-03-15 15:22:24,353] {base_aws.py:90} INFO - Retrieving region_name from Connection.extra_config['region_name']
[2022-03-15 15:22:24,742] {base_aws.py:190} INFO - Credentials retrieved from login
[2022-03-15 15:22:24,744] {base_aws.py:90} INFO - Retrieving region_name from Connection.extra_config['region_name']
[2022-03-15 15:22:25,144] {base_aws.py:190} INFO - Credentials retrieved from login
[2022-03-15 15:22:25,145] {base_aws.py:90} INFO - Retrieving region_name from Connection.extra_config['region_name']
[2022-03-15 15:22:25,606] {base_aws.py:190} INFO - Credentials retrieved from login
[2022-03-15 15:22:25,609] {base_aws.py:90} INFO - Retrieving region_name from Connection.extra_config['region_name']
[2022-03-15 15:22:26,069] {base_aws.py:190} INFO - Credentials retrieved from login
[2022-03-15 15:22:26,070] {base_aws.py:90} INFO - Retrieving region_name from Connection.extra_config['region_name']
[2022-03-15 15:22:26,587] {base_aws.py:190} INFO - Credentials retrieved from login
[2022-03-15 15:22:26,589] {base_aws.py:90} INFO - Retrieving region_name from Connection.extra_config['region_name']
[2022-03-15 15:22:26,980] {base_aws.py:190} INFO - Credentials retrieved from login
[2022-03-15 15:22:26,981] {base_aws.py:90} INFO - Retrieving region_name from Connection.extra_config['region_name']
[2022-03-15 15:22:27,468] {base_aws.py:190} INFO - Credentials retrieved from login
[2022-03-15 15:22:27,469] {base_aws.py:90} INFO - Retrieving region_name from Connection.extra_config['region_name']
[2022-03-15 15:22:27,895] {base_aws.py:190} INFO - Credentials retrieved from login
[2022-03-15 15:22:27,897] {base_aws.py:90} INFO - Retrieving region_name from Connection.extra_config['region_name']
[2022-03-15 15:22:28,344] {base_aws.py:190} INFO - Credentials retrieved from login
[2022-03-15 15:22:28,345] {base_aws.py:90} INFO - Retrieving region_name from Connection.extra_config['region_name']
[2022-03-15 15:22:28,930] {base_aws.py:190} INFO - Credentials retrieved from login
[2022-03-15 15:22:28,931] {base_aws.py:90} INFO - Retrieving region_name from Connection.extra_config['region_name']
[2022-03-15 15:22:29,310] {base_aws.py:190} INFO - Credentials retrieved from login
[2022-03-15 15:22:29,311] {base_aws.py:90} INFO - Retrieving region_name from Connection.extra_config['region_name']
[2022-03-15 15:22:29,709] {logging_mixin.py:109} INFO -                                                     title  servings  ...                                          equipment                                        ingredients
id                                                                   ...                                                                                                      
635675                                  Boozy Bbq Chicken         6  ...  [frying pan, paper towels, skewers, bowl, sauc...  [drink, salt and pepper, whole chicken, pepper...
637162  Carrot and Cabbage Salad With Coriander+cumin ...         1  ...                                                NaN  [cabbage, lime juice, spices, fresh cilantro, ...
641975                          Easy Ginger Beef Broccoli         4  ...                            [wok, frying pan, bowl]  [broth, soy sauce, ginger, broccoli, beef, sug...
644387                                      Garlicky Kale         2  ...                                              [pot]                 [vinegar, olive oil, kale, garlic]
648320                         Jade Buddha Salmon Tartare         2  ...                                                NaN                              [vinegar, lime juice]
659143  Salmon, Watercress, Fennel and Baby Beetroot S...         4  ...           [whisk, slotted spoon, frying pan, bowl]  [beet, black pepper, fennel, wine, water, wate...
660405     Smoky Black Bean Soup With Sweet Potato & Kale         6  ...                       [pot, baking sheet, blender]  [broth, onion, salt and pepper, spread, pepper...
663985               Turkey and Rice Stuffed Acorn Squash         6  ...                                 [oven, frying pan]  [vegeta, red pepper, spinach, salt and pepper,...
715446                              Slow Cooker Beef Stew         6  ...                                      [slow cooker]  [cream of mushroom soup, salt and pepper, onio...
715543                                 Homemade Guacamole         4  ...                                                NaN                                                NaN
715594             Homemade Garlic and Basil French Fries         2  ...                                                NaN                                                NaN
716268                        African Chicken Peanut Stew         1  ...                                        [pot, bowl]  [salt and pepper, ginger, sweet potato, potato...
716408  Greek-Style Baked Fish: Fresh, Simple, and Del...         4  ...                                 [oven, baking pan]  [oregano, fresh basil, tomato, salt and pepper...
716426  Cauliflower, Brown Rice, and Vegetable Fried Rice         8  ...                       [frying pan, food processor]  [cauliflower rice, cauliflower florets, butter...
729366                                     Plantain Salad         1  ...                                 [bowl, frying pan]  [plantain, shrimp, vegetable, vegetable oil, p...
766453                                 Hummus and Za'atar         4  ...      [bowl, frying pan, sauce pan, food processor]  [toast, zaatar, vegetable, paprika, salt, seas...
769774  Shredded Roast Beef Stuffed Sweet Potatoes (Wh...         4  ...                                                NaN                                                NaN
794349                   Broccoli and Chickpea Rice Salad         6  ...                          [whisk, frying pan, bowl]                 [broccoli, seasoning, cooking oil]
798400  Spicy Black-Eyed Pea Curry with Swiss Chard an...         6  ...  [frying pan, oven, sauce pan, roasting pan, si...  [chili pepper, lemon juice, shallot, spices, p...

[19 rows x 6 columns]
[2022-03-15 15:23:21,177] {process_utils.py:120} INFO - Sending Signals.SIGTERM to group 28253. PIDs of all processes in the group: [28253]
[2022-03-15 15:23:21,177] {process_utils.py:75} INFO - Sending the signal Signals.SIGTERM to group 28253
[2022-03-15 15:23:25,940] {taskinstance.py:1027} INFO - Dependencies not met for <TaskInstance: simple_dag.to_sql scheduled__2022-03-15T15:20:51.391365+00:00 [running]>, dependency 'Task Instance Not Running' FAILED: Task is in the running state
[2022-03-15 15:23:25,940] {taskinstance.py:1027} INFO - Dependencies not met for <TaskInstance: simple_dag.to_sql scheduled__2022-03-15T15:20:51.391365+00:00 [running]>, dependency 'Task Instance State' FAILED: Task is in the 'running' state.
[2022-03-15 15:23:25,941] {local_task_job.py:99} INFO - Task is not able to be run
[2022-03-15 15:43:22,237] {taskinstance.py:1413} ERROR - Received SIGTERM. Terminating subprocesses.
[2022-03-15 15:43:22,282] {taskinstance.py:1718} ERROR - Task failed with exception
Traceback (most recent call last):
  File "/opt/anaconda3/lib/python3.9/site-packages/airflow/models/taskinstance.py", line 1334, in _run_raw_task
    self._execute_task_with_callbacks(context)
  File "/opt/anaconda3/lib/python3.9/site-packages/airflow/models/taskinstance.py", line 1460, in _execute_task_with_callbacks
    result = self._execute_task(context, self.task)
  File "/opt/anaconda3/lib/python3.9/site-packages/airflow/models/taskinstance.py", line 1516, in _execute_task
    result = execute_callable(context=context)
  File "/opt/anaconda3/lib/python3.9/site-packages/airflow/operators/python.py", line 174, in execute
    return_value = self.execute_callable()
  File "/opt/anaconda3/lib/python3.9/site-packages/airflow/operators/python.py", line 188, in execute_callable
    return self.python_callable(*self.op_args, **self.op_kwargs)
  File "/Users/HomeFolder/airflow/dags/simple_dag.py", line 180, in to_sql
    #    recipes.to_sql('recipes',engine, if_exists='replace')
  File "/opt/anaconda3/lib/python3.9/site-packages/pandas/core/generic.py", line 2872, in to_sql
    sql.to_sql(
  File "/opt/anaconda3/lib/python3.9/site-packages/pandas/io/sql.py", line 717, in to_sql
    pandas_sql.to_sql(
  File "/opt/anaconda3/lib/python3.9/site-packages/pandas/io/sql.py", line 1751, in to_sql
    table = self.prep_table(
  File "/opt/anaconda3/lib/python3.9/site-packages/pandas/io/sql.py", line 1650, in prep_table
    table.create()
  File "/opt/anaconda3/lib/python3.9/site-packages/pandas/io/sql.py", line 860, in create
    self.pd_sql.drop_table(self.name, self.schema)
  File "/opt/anaconda3/lib/python3.9/site-packages/pandas/io/sql.py", line 1810, in drop_table
    self.get_table(table_name, schema).drop()
  File "/opt/anaconda3/lib/python3.9/site-packages/sqlalchemy/sql/schema.py", line 942, in drop
    bind._run_visitor(ddl.SchemaDropper, self, checkfirst=checkfirst)
  File "/opt/anaconda3/lib/python3.9/site-packages/sqlalchemy/engine/base.py", line 1656, in _run_visitor
    visitorcallable(self.dialect, self, **kwargs).traverse_single(element)
  File "/opt/anaconda3/lib/python3.9/site-packages/sqlalchemy/sql/visitors.py", line 145, in traverse_single
    return meth(obj, **kw)
  File "/opt/anaconda3/lib/python3.9/site-packages/sqlalchemy/sql/ddl.py", line 1018, in visit_table
    self.connection.execute(DropTable(table))
  File "/opt/anaconda3/lib/python3.9/site-packages/sqlalchemy/engine/base.py", line 1011, in execute
    return meth(self, multiparams, params)
  File "/opt/anaconda3/lib/python3.9/site-packages/sqlalchemy/sql/ddl.py", line 72, in _execute_on_connection
    return connection._execute_ddl(self, multiparams, params)
  File "/opt/anaconda3/lib/python3.9/site-packages/sqlalchemy/engine/base.py", line 1068, in _execute_ddl
    ret = self._execute_context(
  File "/opt/anaconda3/lib/python3.9/site-packages/sqlalchemy/engine/base.py", line 1316, in _execute_context
    self._handle_dbapi_exception(
  File "/opt/anaconda3/lib/python3.9/site-packages/sqlalchemy/engine/base.py", line 1514, in _handle_dbapi_exception
    util.raise_(exc_info[1], with_traceback=exc_info[2])
  File "/opt/anaconda3/lib/python3.9/site-packages/sqlalchemy/util/compat.py", line 182, in raise_
    raise exception
  File "/opt/anaconda3/lib/python3.9/site-packages/sqlalchemy/engine/base.py", line 1276, in _execute_context
    self.dialect.do_execute(
  File "/opt/anaconda3/lib/python3.9/site-packages/sqlalchemy/engine/default.py", line 608, in do_execute
    cursor.execute(statement, parameters)
  File "/opt/anaconda3/lib/python3.9/encodings/utf_8.py", line 15, in decode
    def decode(input, errors='strict'):
  File "/opt/anaconda3/lib/python3.9/site-packages/airflow/models/taskinstance.py", line 1415, in signal_handler
    raise AirflowException("Task received SIGTERM signal")
airflow.exceptions.AirflowException: Task received SIGTERM signal
[2022-03-15 15:43:22,530] {taskinstance.py:1272} INFO - Marking task as FAILED. dag_id=simple_dag, task_id=to_sql, execution_date=20220315T152051, start_date=20220315T202219, end_date=20220315T204322
[2022-03-15 15:43:22,544] {standard_task_runner.py:89} ERROR - Failed to execute job 343 for task to_sql
Traceback (most recent call last):
  File "/opt/anaconda3/lib/python3.9/site-packages/airflow/models/taskinstance.py", line 1334, in _run_raw_task
    self._execute_task_with_callbacks(context)
  File "/opt/anaconda3/lib/python3.9/site-packages/airflow/models/taskinstance.py", line 1460, in _execute_task_with_callbacks
    result = self._execute_task(context, self.task)
  File "/opt/anaconda3/lib/python3.9/site-packages/airflow/models/taskinstance.py", line 1516, in _execute_task
    result = execute_callable(context=context)
  File "/opt/anaconda3/lib/python3.9/site-packages/airflow/operators/python.py", line 174, in execute
    return_value = self.execute_callable()
  File "/opt/anaconda3/lib/python3.9/site-packages/airflow/operators/python.py", line 188, in execute_callable
    return self.python_callable(*self.op_args, **self.op_kwargs)
  File "/Users/HomeFolder/airflow/dags/simple_dag.py", line 180, in to_sql
    #    recipes.to_sql('recipes',engine, if_exists='replace')
  File "/opt/anaconda3/lib/python3.9/site-packages/pandas/core/generic.py", line 2872, in to_sql
    sql.to_sql(
  File "/opt/anaconda3/lib/python3.9/site-packages/pandas/io/sql.py", line 717, in to_sql
    pandas_sql.to_sql(
  File "/opt/anaconda3/lib/python3.9/site-packages/pandas/io/sql.py", line 1751, in to_sql
    table = self.prep_table(
  File "/opt/anaconda3/lib/python3.9/site-packages/pandas/io/sql.py", line 1650, in prep_table
    table.create()
  File "/opt/anaconda3/lib/python3.9/site-packages/pandas/io/sql.py", line 860, in create
    self.pd_sql.drop_table(self.name, self.schema)
  File "/opt/anaconda3/lib/python3.9/site-packages/pandas/io/sql.py", line 1810, in drop_table
    self.get_table(table_name, schema).drop()
  File "/opt/anaconda3/lib/python3.9/site-packages/sqlalchemy/sql/schema.py", line 942, in drop
    bind._run_visitor(ddl.SchemaDropper, self, checkfirst=checkfirst)
  File "/opt/anaconda3/lib/python3.9/site-packages/sqlalchemy/engine/base.py", line 1656, in _run_visitor
    visitorcallable(self.dialect, self, **kwargs).traverse_single(element)
  File "/opt/anaconda3/lib/python3.9/site-packages/sqlalchemy/sql/visitors.py", line 145, in traverse_single
    return meth(obj, **kw)
  File "/opt/anaconda3/lib/python3.9/site-packages/sqlalchemy/sql/ddl.py", line 1018, in visit_table
    self.connection.execute(DropTable(table))
  File "/opt/anaconda3/lib/python3.9/site-packages/sqlalchemy/engine/base.py", line 1011, in execute
    return meth(self, multiparams, params)
  File "/opt/anaconda3/lib/python3.9/site-packages/sqlalchemy/sql/ddl.py", line 72, in _execute_on_connection
    return connection._execute_ddl(self, multiparams, params)
  File "/opt/anaconda3/lib/python3.9/site-packages/sqlalchemy/engine/base.py", line 1068, in _execute_ddl
    ret = self._execute_context(
  File "/opt/anaconda3/lib/python3.9/site-packages/sqlalchemy/engine/base.py", line 1316, in _execute_context
    self._handle_dbapi_exception(
  File "/opt/anaconda3/lib/python3.9/site-packages/sqlalchemy/engine/base.py", line 1514, in _handle_dbapi_exception
    util.raise_(exc_info[1], with_traceback=exc_info[2])
  File "/opt/anaconda3/lib/python3.9/site-packages/sqlalchemy/util/compat.py", line 182, in raise_
    raise exception
  File "/opt/anaconda3/lib/python3.9/site-packages/sqlalchemy/engine/base.py", line 1276, in _execute_context
    self.dialect.do_execute(
  File "/opt/anaconda3/lib/python3.9/site-packages/sqlalchemy/engine/default.py", line 608, in do_execute
    cursor.execute(statement, parameters)
  File "/opt/anaconda3/lib/python3.9/encodings/utf_8.py", line 15, in decode
    def decode(input, errors='strict'):
  File "/opt/anaconda3/lib/python3.9/site-packages/airflow/models/taskinstance.py", line 1415, in signal_handler
    raise AirflowException("Task received SIGTERM signal")
airflow.exceptions.AirflowException: Task received SIGTERM signal

During handling of the above exception, another exception occurred:

Traceback (most recent call last):
  File "/opt/anaconda3/lib/python3.9/site-packages/sqlalchemy/engine/base.py", line 1276, in _execute_context
    self.dialect.do_execute(
  File "/opt/anaconda3/lib/python3.9/site-packages/sqlalchemy/engine/default.py", line 608, in do_execute
    cursor.execute(statement, parameters)
sqlite3.IntegrityError: FOREIGN KEY constraint failed

The above exception was the direct cause of the following exception:

Traceback (most recent call last):
  File "/opt/anaconda3/lib/python3.9/site-packages/airflow/task/task_runner/standard_task_runner.py", line 85, in _start_by_fork
    args.func(args, dag=self.dag)
  File "/opt/anaconda3/lib/python3.9/site-packages/airflow/cli/cli_parser.py", line 48, in command
    return func(*args, **kwargs)
  File "/opt/anaconda3/lib/python3.9/site-packages/airflow/utils/cli.py", line 92, in wrapper
    return f(*args, **kwargs)
  File "/opt/anaconda3/lib/python3.9/site-packages/airflow/cli/commands/task_command.py", line 298, in task_run
    _run_task_by_selected_method(args, dag, ti)
  File "/opt/anaconda3/lib/python3.9/site-packages/airflow/cli/commands/task_command.py", line 107, in _run_task_by_selected_method
    _run_raw_task(args, ti)
  File "/opt/anaconda3/lib/python3.9/site-packages/airflow/cli/commands/task_command.py", line 180, in _run_raw_task
    ti._run_raw_task(
  File "/opt/anaconda3/lib/python3.9/site-packages/airflow/utils/session.py", line 70, in wrapper
    return func(*args, session=session, **kwargs)
  File "/opt/anaconda3/lib/python3.9/site-packages/airflow/models/taskinstance.py", line 1387, in _run_raw_task
    self.handle_failure(e, test_mode, error_file=error_file, session=session)
  File "/opt/anaconda3/lib/python3.9/site-packages/airflow/utils/session.py", line 67, in wrapper
    return func(*args, **kwargs)
  File "/opt/anaconda3/lib/python3.9/site-packages/airflow/models/taskinstance.py", line 1773, in handle_failure
    session.flush()
  File "/opt/anaconda3/lib/python3.9/site-packages/sqlalchemy/orm/session.py", line 2540, in flush
    self._flush(objects)
  File "/opt/anaconda3/lib/python3.9/site-packages/sqlalchemy/orm/session.py", line 2682, in _flush
    transaction.rollback(_capture_exception=True)
  File "/opt/anaconda3/lib/python3.9/site-packages/sqlalchemy/util/langhelpers.py", line 68, in __exit__
    compat.raise_(
  File "/opt/anaconda3/lib/python3.9/site-packages/sqlalchemy/util/compat.py", line 182, in raise_
    raise exception
  File "/opt/anaconda3/lib/python3.9/site-packages/sqlalchemy/orm/session.py", line 2642, in _flush
    flush_context.execute()
  File "/opt/anaconda3/lib/python3.9/site-packages/sqlalchemy/orm/unitofwork.py", line 422, in execute
    rec.execute(self)
  File "/opt/anaconda3/lib/python3.9/site-packages/sqlalchemy/orm/unitofwork.py", line 586, in execute
    persistence.save_obj(
  File "/opt/anaconda3/lib/python3.9/site-packages/sqlalchemy/orm/persistence.py", line 230, in save_obj
    _emit_update_statements(
  File "/opt/anaconda3/lib/python3.9/site-packages/sqlalchemy/orm/persistence.py", line 994, in _emit_update_statements
    c = cached_connections[connection].execute(
  File "/opt/anaconda3/lib/python3.9/site-packages/sqlalchemy/engine/base.py", line 1011, in execute
    return meth(self, multiparams, params)
  File "/opt/anaconda3/lib/python3.9/site-packages/sqlalchemy/sql/elements.py", line 298, in _execute_on_connection
    return connection._execute_clauseelement(self, multiparams, params)
  File "/opt/anaconda3/lib/python3.9/site-packages/sqlalchemy/engine/base.py", line 1124, in _execute_clauseelement
    ret = self._execute_context(
  File "/opt/anaconda3/lib/python3.9/site-packages/sqlalchemy/engine/base.py", line 1316, in _execute_context
    self._handle_dbapi_exception(
  File "/opt/anaconda3/lib/python3.9/site-packages/sqlalchemy/engine/base.py", line 1510, in _handle_dbapi_exception
    util.raise_(
  File "/opt/anaconda3/lib/python3.9/site-packages/sqlalchemy/util/compat.py", line 182, in raise_
    raise exception
  File "/opt/anaconda3/lib/python3.9/site-packages/sqlalchemy/engine/base.py", line 1276, in _execute_context
    self.dialect.do_execute(
  File "/opt/anaconda3/lib/python3.9/site-packages/sqlalchemy/engine/default.py", line 608, in do_execute
    cursor.execute(statement, parameters)
sqlalchemy.exc.IntegrityError: (sqlite3.IntegrityError) FOREIGN KEY constraint failed
[SQL: UPDATE dag_run SET queued_at=?, execution_date=?, start_date=?, run_id=?, creating_job_id=?, data_interval_start=?, data_interval_end=?, last_scheduling_decision=?, dag_hash=? WHERE dag_run.id = ?]
[parameters: ('2022-03-15 20:22:15.625995', '2022-03-15 15:20:51.391365', '2022-03-15 20:22:15.656846', 'scheduled__2022-03-15T15:20:51.391365+00:00', 342, '2022-03-15 15:20:51.391365', '2022-03-15 15:20:51.391365', '2022-03-15 20:22:15.676853', '046b829bb5427c4501bbf6a69a074d0d', 5)]
(Background on this error at: http://sqlalche.me/e/13/gkpj)
