[2022-03-14 13:25:32,020] {taskinstance.py:1037} INFO - Dependencies all met for <TaskInstance: simple_dag.upload_to_bucket scheduled__2022-03-14T13:22:00+00:00 [queued]>
[2022-03-14 13:25:32,028] {taskinstance.py:1037} INFO - Dependencies all met for <TaskInstance: simple_dag.upload_to_bucket scheduled__2022-03-14T13:22:00+00:00 [queued]>
[2022-03-14 13:25:32,029] {taskinstance.py:1243} INFO - 
--------------------------------------------------------------------------------
[2022-03-14 13:25:32,029] {taskinstance.py:1244} INFO - Starting attempt 1 of 1
[2022-03-14 13:25:32,029] {taskinstance.py:1245} INFO - 
--------------------------------------------------------------------------------
[2022-03-14 13:25:32,039] {taskinstance.py:1264} INFO - Executing <Task(PythonOperator): upload_to_bucket> on 2022-03-14 13:22:00+00:00
[2022-03-14 13:25:32,042] {standard_task_runner.py:52} INFO - Started process 84943 to run task
[2022-03-14 13:25:32,048] {standard_task_runner.py:76} INFO - Running: ['airflow', 'tasks', 'run', 'simple_dag', 'upload_to_bucket', 'scheduled__2022-03-14T13:22:00+00:00', '--job-id', '164', '--raw', '--subdir', 'DAGS_FOLDER/simple_dag.py', '--cfg-path', '/var/folders/tl/ljh9dpdd2fnbgmc62qc2b49h0000gn/T/tmpmea8py_x', '--error-file', '/var/folders/tl/ljh9dpdd2fnbgmc62qc2b49h0000gn/T/tmpv3y120mu']
[2022-03-14 13:25:32,051] {standard_task_runner.py:77} INFO - Job 164: Subtask upload_to_bucket
[2022-03-14 13:25:32,119] {logging_mixin.py:109} INFO - Running <TaskInstance: simple_dag.upload_to_bucket scheduled__2022-03-14T13:22:00+00:00 [running]> on host 1.0.0.0.0.0.0.0.0.0.0.0.0.0.0.0.0.0.0.0.0.0.0.0.0.0.0.0.0.0.0.0.ip6.arpa
[2022-03-14 13:25:32,178] {taskinstance.py:1429} INFO - Exporting the following env vars:
AIRFLOW_CTX_DAG_OWNER=airflow
AIRFLOW_CTX_DAG_ID=simple_dag
AIRFLOW_CTX_TASK_ID=upload_to_bucket
AIRFLOW_CTX_EXECUTION_DATE=2022-03-14T13:22:00+00:00
AIRFLOW_CTX_DAG_RUN_ID=scheduled__2022-03-14T13:22:00+00:00
[2022-03-14 13:25:32,181] {taskinstance.py:1718} ERROR - Task failed with exception
Traceback (most recent call last):
  File "/opt/anaconda3/lib/python3.9/site-packages/airflow/models/taskinstance.py", line 1334, in _run_raw_task
    self._execute_task_with_callbacks(context)
  File "/opt/anaconda3/lib/python3.9/site-packages/airflow/models/taskinstance.py", line 1460, in _execute_task_with_callbacks
    result = self._execute_task(context, self.task)
  File "/opt/anaconda3/lib/python3.9/site-packages/airflow/models/taskinstance.py", line 1516, in _execute_task
    result = execute_callable(context=context)
  File "/opt/anaconda3/lib/python3.9/site-packages/airflow/operators/python.py", line 174, in execute
    return_value = self.execute_callable()
  File "/opt/anaconda3/lib/python3.9/site-packages/airflow/operators/python.py", line 188, in execute_callable
    return self.python_callable(*self.op_args, **self.op_kwargs)
  File "/Users/HomeFolder/airflow/dags/simple_dag.py", line 26, in request_user
    key=''.join("raw/",file),
TypeError: str.join() takes exactly one argument (2 given)
[2022-03-14 13:25:32,197] {taskinstance.py:1272} INFO - Marking task as FAILED. dag_id=simple_dag, task_id=upload_to_bucket, execution_date=20220314T132200, start_date=20220314T182532, end_date=20220314T182532
[2022-03-14 13:25:32,212] {standard_task_runner.py:89} ERROR - Failed to execute job 164 for task upload_to_bucket
Traceback (most recent call last):
  File "/opt/anaconda3/lib/python3.9/site-packages/airflow/task/task_runner/standard_task_runner.py", line 85, in _start_by_fork
    args.func(args, dag=self.dag)
  File "/opt/anaconda3/lib/python3.9/site-packages/airflow/cli/cli_parser.py", line 48, in command
    return func(*args, **kwargs)
  File "/opt/anaconda3/lib/python3.9/site-packages/airflow/utils/cli.py", line 92, in wrapper
    return f(*args, **kwargs)
  File "/opt/anaconda3/lib/python3.9/site-packages/airflow/cli/commands/task_command.py", line 298, in task_run
    _run_task_by_selected_method(args, dag, ti)
  File "/opt/anaconda3/lib/python3.9/site-packages/airflow/cli/commands/task_command.py", line 107, in _run_task_by_selected_method
    _run_raw_task(args, ti)
  File "/opt/anaconda3/lib/python3.9/site-packages/airflow/cli/commands/task_command.py", line 180, in _run_raw_task
    ti._run_raw_task(
  File "/opt/anaconda3/lib/python3.9/site-packages/airflow/utils/session.py", line 70, in wrapper
    return func(*args, session=session, **kwargs)
  File "/opt/anaconda3/lib/python3.9/site-packages/airflow/models/taskinstance.py", line 1334, in _run_raw_task
    self._execute_task_with_callbacks(context)
  File "/opt/anaconda3/lib/python3.9/site-packages/airflow/models/taskinstance.py", line 1460, in _execute_task_with_callbacks
    result = self._execute_task(context, self.task)
  File "/opt/anaconda3/lib/python3.9/site-packages/airflow/models/taskinstance.py", line 1516, in _execute_task
    result = execute_callable(context=context)
  File "/opt/anaconda3/lib/python3.9/site-packages/airflow/operators/python.py", line 174, in execute
    return_value = self.execute_callable()
  File "/opt/anaconda3/lib/python3.9/site-packages/airflow/operators/python.py", line 188, in execute_callable
    return self.python_callable(*self.op_args, **self.op_kwargs)
  File "/Users/HomeFolder/airflow/dags/simple_dag.py", line 26, in request_user
    key=''.join("raw/",file),
TypeError: str.join() takes exactly one argument (2 given)
[2022-03-14 13:25:32,234] {local_task_job.py:154} INFO - Task exited with return code 1
[2022-03-14 13:25:32,252] {local_task_job.py:264} INFO - 0 downstream tasks scheduled from follow-on schedule check
[2022-03-14 13:26:32,788] {taskinstance.py:1037} INFO - Dependencies all met for <TaskInstance: simple_dag.upload_to_bucket scheduled__2022-03-14T13:22:00+00:00 [queued]>
[2022-03-14 13:26:32,800] {taskinstance.py:1037} INFO - Dependencies all met for <TaskInstance: simple_dag.upload_to_bucket scheduled__2022-03-14T13:22:00+00:00 [queued]>
[2022-03-14 13:26:32,801] {taskinstance.py:1243} INFO - 
--------------------------------------------------------------------------------
[2022-03-14 13:26:32,801] {taskinstance.py:1244} INFO - Starting attempt 1 of 1
[2022-03-14 13:26:32,801] {taskinstance.py:1245} INFO - 
--------------------------------------------------------------------------------
[2022-03-14 13:26:32,812] {taskinstance.py:1264} INFO - Executing <Task(PythonOperator): upload_to_bucket> on 2022-03-14 13:22:00+00:00
[2022-03-14 13:26:32,815] {standard_task_runner.py:52} INFO - Started process 84988 to run task
[2022-03-14 13:26:32,822] {standard_task_runner.py:76} INFO - Running: ['airflow', 'tasks', 'run', 'simple_dag', 'upload_to_bucket', 'scheduled__2022-03-14T13:22:00+00:00', '--job-id', '165', '--raw', '--subdir', 'DAGS_FOLDER/simple_dag.py', '--cfg-path', '/var/folders/tl/ljh9dpdd2fnbgmc62qc2b49h0000gn/T/tmpc6cq4m2r', '--error-file', '/var/folders/tl/ljh9dpdd2fnbgmc62qc2b49h0000gn/T/tmprga7wzz8']
[2022-03-14 13:26:32,826] {standard_task_runner.py:77} INFO - Job 165: Subtask upload_to_bucket
[2022-03-14 13:26:32,885] {logging_mixin.py:109} INFO - Running <TaskInstance: simple_dag.upload_to_bucket scheduled__2022-03-14T13:22:00+00:00 [running]> on host 1.0.0.0.0.0.0.0.0.0.0.0.0.0.0.0.0.0.0.0.0.0.0.0.0.0.0.0.0.0.0.0.ip6.arpa
[2022-03-14 13:26:32,934] {taskinstance.py:1429} INFO - Exporting the following env vars:
AIRFLOW_CTX_DAG_OWNER=airflow
AIRFLOW_CTX_DAG_ID=simple_dag
AIRFLOW_CTX_TASK_ID=upload_to_bucket
AIRFLOW_CTX_EXECUTION_DATE=2022-03-14T13:22:00+00:00
AIRFLOW_CTX_DAG_RUN_ID=scheduled__2022-03-14T13:22:00+00:00
[2022-03-14 13:26:32,937] {taskinstance.py:1718} ERROR - Task failed with exception
Traceback (most recent call last):
  File "/opt/anaconda3/lib/python3.9/site-packages/airflow/models/taskinstance.py", line 1334, in _run_raw_task
    self._execute_task_with_callbacks(context)
  File "/opt/anaconda3/lib/python3.9/site-packages/airflow/models/taskinstance.py", line 1460, in _execute_task_with_callbacks
    result = self._execute_task(context, self.task)
  File "/opt/anaconda3/lib/python3.9/site-packages/airflow/models/taskinstance.py", line 1516, in _execute_task
    result = execute_callable(context=context)
  File "/opt/anaconda3/lib/python3.9/site-packages/airflow/operators/python.py", line 174, in execute
    return_value = self.execute_callable()
  File "/opt/anaconda3/lib/python3.9/site-packages/airflow/operators/python.py", line 188, in execute_callable
    return self.python_callable(*self.op_args, **self.op_kwargs)
  File "/Users/HomeFolder/airflow/dags/simple_dag.py", line 26, in request_user
    key=''.join("raw/",file),
TypeError: str.join() takes exactly one argument (2 given)
[2022-03-14 13:26:32,950] {taskinstance.py:1272} INFO - Marking task as FAILED. dag_id=simple_dag, task_id=upload_to_bucket, execution_date=20220314T132200, start_date=20220314T182632, end_date=20220314T182632
[2022-03-14 13:26:32,964] {standard_task_runner.py:89} ERROR - Failed to execute job 165 for task upload_to_bucket
Traceback (most recent call last):
  File "/opt/anaconda3/lib/python3.9/site-packages/airflow/task/task_runner/standard_task_runner.py", line 85, in _start_by_fork
    args.func(args, dag=self.dag)
  File "/opt/anaconda3/lib/python3.9/site-packages/airflow/cli/cli_parser.py", line 48, in command
    return func(*args, **kwargs)
  File "/opt/anaconda3/lib/python3.9/site-packages/airflow/utils/cli.py", line 92, in wrapper
    return f(*args, **kwargs)
  File "/opt/anaconda3/lib/python3.9/site-packages/airflow/cli/commands/task_command.py", line 298, in task_run
    _run_task_by_selected_method(args, dag, ti)
  File "/opt/anaconda3/lib/python3.9/site-packages/airflow/cli/commands/task_command.py", line 107, in _run_task_by_selected_method
    _run_raw_task(args, ti)
  File "/opt/anaconda3/lib/python3.9/site-packages/airflow/cli/commands/task_command.py", line 180, in _run_raw_task
    ti._run_raw_task(
  File "/opt/anaconda3/lib/python3.9/site-packages/airflow/utils/session.py", line 70, in wrapper
    return func(*args, session=session, **kwargs)
  File "/opt/anaconda3/lib/python3.9/site-packages/airflow/models/taskinstance.py", line 1334, in _run_raw_task
    self._execute_task_with_callbacks(context)
  File "/opt/anaconda3/lib/python3.9/site-packages/airflow/models/taskinstance.py", line 1460, in _execute_task_with_callbacks
    result = self._execute_task(context, self.task)
  File "/opt/anaconda3/lib/python3.9/site-packages/airflow/models/taskinstance.py", line 1516, in _execute_task
    result = execute_callable(context=context)
  File "/opt/anaconda3/lib/python3.9/site-packages/airflow/operators/python.py", line 174, in execute
    return_value = self.execute_callable()
  File "/opt/anaconda3/lib/python3.9/site-packages/airflow/operators/python.py", line 188, in execute_callable
    return self.python_callable(*self.op_args, **self.op_kwargs)
  File "/Users/HomeFolder/airflow/dags/simple_dag.py", line 26, in request_user
    key=''.join("raw/",file),
TypeError: str.join() takes exactly one argument (2 given)
[2022-03-14 13:26:33,004] {local_task_job.py:154} INFO - Task exited with return code 1
[2022-03-14 13:26:33,024] {local_task_job.py:264} INFO - 0 downstream tasks scheduled from follow-on schedule check
