[2022-03-14 13:29:04,900] {taskinstance.py:1037} INFO - Dependencies all met for <TaskInstance: simple_dag.upload_to_bucket scheduled__2022-03-14T13:30:00+00:00 [queued]>
[2022-03-14 13:29:04,907] {taskinstance.py:1037} INFO - Dependencies all met for <TaskInstance: simple_dag.upload_to_bucket scheduled__2022-03-14T13:30:00+00:00 [queued]>
[2022-03-14 13:29:04,907] {taskinstance.py:1243} INFO - 
--------------------------------------------------------------------------------
[2022-03-14 13:29:04,907] {taskinstance.py:1244} INFO - Starting attempt 1 of 1
[2022-03-14 13:29:04,907] {taskinstance.py:1245} INFO - 
--------------------------------------------------------------------------------
[2022-03-14 13:29:04,916] {taskinstance.py:1264} INFO - Executing <Task(PythonOperator): upload_to_bucket> on 2022-03-14 13:30:00+00:00
[2022-03-14 13:29:04,919] {standard_task_runner.py:52} INFO - Started process 85166 to run task
[2022-03-14 13:29:04,927] {standard_task_runner.py:76} INFO - Running: ['airflow', 'tasks', 'run', 'simple_dag', 'upload_to_bucket', 'scheduled__2022-03-14T13:30:00+00:00', '--job-id', '171', '--raw', '--subdir', 'DAGS_FOLDER/simple_dag.py', '--cfg-path', '/var/folders/tl/ljh9dpdd2fnbgmc62qc2b49h0000gn/T/tmpm46igut1', '--error-file', '/var/folders/tl/ljh9dpdd2fnbgmc62qc2b49h0000gn/T/tmp6gsq1ltz']
[2022-03-14 13:29:04,930] {standard_task_runner.py:77} INFO - Job 171: Subtask upload_to_bucket
[2022-03-14 13:29:04,990] {logging_mixin.py:109} INFO - Running <TaskInstance: simple_dag.upload_to_bucket scheduled__2022-03-14T13:30:00+00:00 [running]> on host 1.0.0.0.0.0.0.0.0.0.0.0.0.0.0.0.0.0.0.0.0.0.0.0.0.0.0.0.0.0.0.0.ip6.arpa
[2022-03-14 13:29:05,037] {taskinstance.py:1429} INFO - Exporting the following env vars:
AIRFLOW_CTX_DAG_OWNER=airflow
AIRFLOW_CTX_DAG_ID=simple_dag
AIRFLOW_CTX_TASK_ID=upload_to_bucket
AIRFLOW_CTX_EXECUTION_DATE=2022-03-14T13:30:00+00:00
AIRFLOW_CTX_DAG_RUN_ID=scheduled__2022-03-14T13:30:00+00:00
[2022-03-14 13:29:05,049] {base_aws.py:190} INFO - Credentials retrieved from login
[2022-03-14 13:29:05,050] {base_aws.py:90} INFO - Retrieving region_name from Connection.extra_config['region_name']
[2022-03-14 13:29:05,381] {taskinstance.py:1718} ERROR - Task failed with exception
Traceback (most recent call last):
  File "/opt/anaconda3/lib/python3.9/site-packages/airflow/models/taskinstance.py", line 1334, in _run_raw_task
    self._execute_task_with_callbacks(context)
  File "/opt/anaconda3/lib/python3.9/site-packages/airflow/models/taskinstance.py", line 1460, in _execute_task_with_callbacks
    result = self._execute_task(context, self.task)
  File "/opt/anaconda3/lib/python3.9/site-packages/airflow/models/taskinstance.py", line 1516, in _execute_task
    result = execute_callable(context=context)
  File "/opt/anaconda3/lib/python3.9/site-packages/airflow/operators/python.py", line 174, in execute
    return_value = self.execute_callable()
  File "/opt/anaconda3/lib/python3.9/site-packages/airflow/operators/python.py", line 188, in execute_callable
    return self.python_callable(*self.op_args, **self.op_kwargs)
  File "/Users/HomeFolder/airflow/dags/simple_dag.py", line 24, in request_user
    s3_hook.load_file(
  File "/opt/anaconda3/lib/python3.9/site-packages/airflow/providers/amazon/aws/hooks/s3.py", line 62, in wrapper
    return func(*bound_args.args, **bound_args.kwargs)
  File "/opt/anaconda3/lib/python3.9/site-packages/airflow/providers/amazon/aws/hooks/s3.py", line 90, in wrapper
    return func(*bound_args.args, **bound_args.kwargs)
  File "/opt/anaconda3/lib/python3.9/site-packages/airflow/providers/amazon/aws/hooks/s3.py", line 474, in load_file
    raise ValueError(f"The key {key} already exists.")
ValueError: The key raw/user-2022-03-14 12:16:52.065604.json already exists.
[2022-03-14 13:29:05,392] {taskinstance.py:1272} INFO - Marking task as FAILED. dag_id=simple_dag, task_id=upload_to_bucket, execution_date=20220314T133000, start_date=20220314T182904, end_date=20220314T182905
[2022-03-14 13:29:05,404] {standard_task_runner.py:89} ERROR - Failed to execute job 171 for task upload_to_bucket
Traceback (most recent call last):
  File "/opt/anaconda3/lib/python3.9/site-packages/airflow/task/task_runner/standard_task_runner.py", line 85, in _start_by_fork
    args.func(args, dag=self.dag)
  File "/opt/anaconda3/lib/python3.9/site-packages/airflow/cli/cli_parser.py", line 48, in command
    return func(*args, **kwargs)
  File "/opt/anaconda3/lib/python3.9/site-packages/airflow/utils/cli.py", line 92, in wrapper
    return f(*args, **kwargs)
  File "/opt/anaconda3/lib/python3.9/site-packages/airflow/cli/commands/task_command.py", line 298, in task_run
    _run_task_by_selected_method(args, dag, ti)
  File "/opt/anaconda3/lib/python3.9/site-packages/airflow/cli/commands/task_command.py", line 107, in _run_task_by_selected_method
    _run_raw_task(args, ti)
  File "/opt/anaconda3/lib/python3.9/site-packages/airflow/cli/commands/task_command.py", line 180, in _run_raw_task
    ti._run_raw_task(
  File "/opt/anaconda3/lib/python3.9/site-packages/airflow/utils/session.py", line 70, in wrapper
    return func(*args, session=session, **kwargs)
  File "/opt/anaconda3/lib/python3.9/site-packages/airflow/models/taskinstance.py", line 1334, in _run_raw_task
    self._execute_task_with_callbacks(context)
  File "/opt/anaconda3/lib/python3.9/site-packages/airflow/models/taskinstance.py", line 1460, in _execute_task_with_callbacks
    result = self._execute_task(context, self.task)
  File "/opt/anaconda3/lib/python3.9/site-packages/airflow/models/taskinstance.py", line 1516, in _execute_task
    result = execute_callable(context=context)
  File "/opt/anaconda3/lib/python3.9/site-packages/airflow/operators/python.py", line 174, in execute
    return_value = self.execute_callable()
  File "/opt/anaconda3/lib/python3.9/site-packages/airflow/operators/python.py", line 188, in execute_callable
    return self.python_callable(*self.op_args, **self.op_kwargs)
  File "/Users/HomeFolder/airflow/dags/simple_dag.py", line 24, in request_user
    s3_hook.load_file(
  File "/opt/anaconda3/lib/python3.9/site-packages/airflow/providers/amazon/aws/hooks/s3.py", line 62, in wrapper
    return func(*bound_args.args, **bound_args.kwargs)
  File "/opt/anaconda3/lib/python3.9/site-packages/airflow/providers/amazon/aws/hooks/s3.py", line 90, in wrapper
    return func(*bound_args.args, **bound_args.kwargs)
  File "/opt/anaconda3/lib/python3.9/site-packages/airflow/providers/amazon/aws/hooks/s3.py", line 474, in load_file
    raise ValueError(f"The key {key} already exists.")
ValueError: The key raw/user-2022-03-14 12:16:52.065604.json already exists.
[2022-03-14 13:29:05,436] {local_task_job.py:154} INFO - Task exited with return code 1
[2022-03-14 13:29:05,457] {local_task_job.py:264} INFO - 0 downstream tasks scheduled from follow-on schedule check
