[2022-03-14 12:13:16,729] {taskinstance.py:1037} INFO - Dependencies all met for <TaskInstance: simple_dag.request_user scheduled__2022-03-14T12:18:00+00:00 [queued]>
[2022-03-14 12:13:16,737] {taskinstance.py:1037} INFO - Dependencies all met for <TaskInstance: simple_dag.request_user scheduled__2022-03-14T12:18:00+00:00 [queued]>
[2022-03-14 12:13:16,737] {taskinstance.py:1243} INFO - 
--------------------------------------------------------------------------------
[2022-03-14 12:13:16,737] {taskinstance.py:1244} INFO - Starting attempt 1 of 1
[2022-03-14 12:13:16,737] {taskinstance.py:1245} INFO - 
--------------------------------------------------------------------------------
[2022-03-14 12:13:16,747] {taskinstance.py:1264} INFO - Executing <Task(PythonOperator): request_user> on 2022-03-14 12:18:00+00:00
[2022-03-14 12:13:16,750] {standard_task_runner.py:52} INFO - Started process 82862 to run task
[2022-03-14 12:13:16,756] {standard_task_runner.py:76} INFO - Running: ['airflow', 'tasks', 'run', 'simple_dag', 'request_user', 'scheduled__2022-03-14T12:18:00+00:00', '--job-id', '148', '--raw', '--subdir', 'DAGS_FOLDER/simple_dag.py', '--cfg-path', '/var/folders/tl/ljh9dpdd2fnbgmc62qc2b49h0000gn/T/tmpsiae7c7z', '--error-file', '/var/folders/tl/ljh9dpdd2fnbgmc62qc2b49h0000gn/T/tmpfcrcs_ve']
[2022-03-14 12:13:16,759] {standard_task_runner.py:77} INFO - Job 148: Subtask request_user
[2022-03-14 12:13:16,814] {logging_mixin.py:109} INFO - Running <TaskInstance: simple_dag.request_user scheduled__2022-03-14T12:18:00+00:00 [running]> on host 1.0.0.0.0.0.0.0.0.0.0.0.0.0.0.0.0.0.0.0.0.0.0.0.0.0.0.0.0.0.0.0.ip6.arpa
[2022-03-14 12:13:16,862] {taskinstance.py:1429} INFO - Exporting the following env vars:
AIRFLOW_CTX_DAG_OWNER=airflow
AIRFLOW_CTX_DAG_ID=simple_dag
AIRFLOW_CTX_TASK_ID=request_user
AIRFLOW_CTX_EXECUTION_DATE=2022-03-14T12:18:00+00:00
AIRFLOW_CTX_DAG_RUN_ID=scheduled__2022-03-14T12:18:00+00:00
[2022-03-14 12:13:16,985] {taskinstance.py:1718} ERROR - Task failed with exception
Traceback (most recent call last):
  File "/opt/anaconda3/lib/python3.9/site-packages/airflow/models/taskinstance.py", line 1334, in _run_raw_task
    self._execute_task_with_callbacks(context)
  File "/opt/anaconda3/lib/python3.9/site-packages/airflow/models/taskinstance.py", line 1460, in _execute_task_with_callbacks
    result = self._execute_task(context, self.task)
  File "/opt/anaconda3/lib/python3.9/site-packages/airflow/models/taskinstance.py", line 1516, in _execute_task
    result = execute_callable(context=context)
  File "/opt/anaconda3/lib/python3.9/site-packages/airflow/operators/python.py", line 174, in execute
    return_value = self.execute_callable()
  File "/opt/anaconda3/lib/python3.9/site-packages/airflow/operators/python.py", line 188, in execute_callable
    return self.python_callable(*self.op_args, **self.op_kwargs)
  File "/Users/HomeFolder/airflow/dags/simple_dag.py", line 19, in request_user
    json.dump(json_data, json_file)
NameError: name 'json' is not defined
[2022-03-14 12:13:17,009] {taskinstance.py:1272} INFO - Marking task as FAILED. dag_id=simple_dag, task_id=request_user, execution_date=20220314T121800, start_date=20220314T171316, end_date=20220314T171317
[2022-03-14 12:13:17,021] {standard_task_runner.py:89} ERROR - Failed to execute job 148 for task request_user
Traceback (most recent call last):
  File "/opt/anaconda3/lib/python3.9/site-packages/airflow/task/task_runner/standard_task_runner.py", line 85, in _start_by_fork
    args.func(args, dag=self.dag)
  File "/opt/anaconda3/lib/python3.9/site-packages/airflow/cli/cli_parser.py", line 48, in command
    return func(*args, **kwargs)
  File "/opt/anaconda3/lib/python3.9/site-packages/airflow/utils/cli.py", line 92, in wrapper
    return f(*args, **kwargs)
  File "/opt/anaconda3/lib/python3.9/site-packages/airflow/cli/commands/task_command.py", line 298, in task_run
    _run_task_by_selected_method(args, dag, ti)
  File "/opt/anaconda3/lib/python3.9/site-packages/airflow/cli/commands/task_command.py", line 107, in _run_task_by_selected_method
    _run_raw_task(args, ti)
  File "/opt/anaconda3/lib/python3.9/site-packages/airflow/cli/commands/task_command.py", line 180, in _run_raw_task
    ti._run_raw_task(
  File "/opt/anaconda3/lib/python3.9/site-packages/airflow/utils/session.py", line 70, in wrapper
    return func(*args, session=session, **kwargs)
  File "/opt/anaconda3/lib/python3.9/site-packages/airflow/models/taskinstance.py", line 1334, in _run_raw_task
    self._execute_task_with_callbacks(context)
  File "/opt/anaconda3/lib/python3.9/site-packages/airflow/models/taskinstance.py", line 1460, in _execute_task_with_callbacks
    result = self._execute_task(context, self.task)
  File "/opt/anaconda3/lib/python3.9/site-packages/airflow/models/taskinstance.py", line 1516, in _execute_task
    result = execute_callable(context=context)
  File "/opt/anaconda3/lib/python3.9/site-packages/airflow/operators/python.py", line 174, in execute
    return_value = self.execute_callable()
  File "/opt/anaconda3/lib/python3.9/site-packages/airflow/operators/python.py", line 188, in execute_callable
    return self.python_callable(*self.op_args, **self.op_kwargs)
  File "/Users/HomeFolder/airflow/dags/simple_dag.py", line 19, in request_user
    json.dump(json_data, json_file)
NameError: name 'json' is not defined
[2022-03-14 12:13:17,062] {local_task_job.py:154} INFO - Task exited with return code 1
[2022-03-14 12:13:17,081] {local_task_job.py:264} INFO - 0 downstream tasks scheduled from follow-on schedule check
[2022-03-14 12:15:07,323] {taskinstance.py:1037} INFO - Dependencies all met for <TaskInstance: simple_dag.request_user scheduled__2022-03-14T12:18:00+00:00 [queued]>
[2022-03-14 12:15:07,331] {taskinstance.py:1037} INFO - Dependencies all met for <TaskInstance: simple_dag.request_user scheduled__2022-03-14T12:18:00+00:00 [queued]>
[2022-03-14 12:15:07,331] {taskinstance.py:1243} INFO - 
--------------------------------------------------------------------------------
[2022-03-14 12:15:07,331] {taskinstance.py:1244} INFO - Starting attempt 1 of 1
[2022-03-14 12:15:07,331] {taskinstance.py:1245} INFO - 
--------------------------------------------------------------------------------
[2022-03-14 12:15:07,340] {taskinstance.py:1264} INFO - Executing <Task(PythonOperator): request_user> on 2022-03-14 12:18:00+00:00
[2022-03-14 12:15:07,344] {standard_task_runner.py:52} INFO - Started process 82926 to run task
[2022-03-14 12:15:07,350] {standard_task_runner.py:76} INFO - Running: ['airflow', 'tasks', 'run', 'simple_dag', 'request_user', 'scheduled__2022-03-14T12:18:00+00:00', '--job-id', '157', '--raw', '--subdir', 'DAGS_FOLDER/simple_dag.py', '--cfg-path', '/var/folders/tl/ljh9dpdd2fnbgmc62qc2b49h0000gn/T/tmpldm11t4o', '--error-file', '/var/folders/tl/ljh9dpdd2fnbgmc62qc2b49h0000gn/T/tmpl98hs0nd']
[2022-03-14 12:15:07,353] {standard_task_runner.py:77} INFO - Job 157: Subtask request_user
[2022-03-14 12:15:07,407] {logging_mixin.py:109} INFO - Running <TaskInstance: simple_dag.request_user scheduled__2022-03-14T12:18:00+00:00 [running]> on host 1.0.0.0.0.0.0.0.0.0.0.0.0.0.0.0.0.0.0.0.0.0.0.0.0.0.0.0.0.0.0.0.ip6.arpa
[2022-03-14 12:15:07,456] {taskinstance.py:1429} INFO - Exporting the following env vars:
AIRFLOW_CTX_DAG_OWNER=airflow
AIRFLOW_CTX_DAG_ID=simple_dag
AIRFLOW_CTX_TASK_ID=request_user
AIRFLOW_CTX_EXECUTION_DATE=2022-03-14T12:18:00+00:00
AIRFLOW_CTX_DAG_RUN_ID=scheduled__2022-03-14T12:18:00+00:00
[2022-03-14 12:15:07,562] {taskinstance.py:1718} ERROR - Task failed with exception
Traceback (most recent call last):
  File "/opt/anaconda3/lib/python3.9/site-packages/airflow/models/taskinstance.py", line 1334, in _run_raw_task
    self._execute_task_with_callbacks(context)
  File "/opt/anaconda3/lib/python3.9/site-packages/airflow/models/taskinstance.py", line 1460, in _execute_task_with_callbacks
    result = self._execute_task(context, self.task)
  File "/opt/anaconda3/lib/python3.9/site-packages/airflow/models/taskinstance.py", line 1516, in _execute_task
    result = execute_callable(context=context)
  File "/opt/anaconda3/lib/python3.9/site-packages/airflow/operators/python.py", line 174, in execute
    return_value = self.execute_callable()
  File "/opt/anaconda3/lib/python3.9/site-packages/airflow/operators/python.py", line 188, in execute_callable
    return self.python_callable(*self.op_args, **self.op_kwargs)
  File "/Users/HomeFolder/airflow/dags/simple_dag.py", line 19, in request_user
    json.dump(json_data, json_file)
NameError: name 'json' is not defined
[2022-03-14 12:15:07,573] {taskinstance.py:1272} INFO - Marking task as FAILED. dag_id=simple_dag, task_id=request_user, execution_date=20220314T121800, start_date=20220314T171507, end_date=20220314T171507
[2022-03-14 12:15:07,585] {standard_task_runner.py:89} ERROR - Failed to execute job 157 for task request_user
Traceback (most recent call last):
  File "/opt/anaconda3/lib/python3.9/site-packages/airflow/task/task_runner/standard_task_runner.py", line 85, in _start_by_fork
    args.func(args, dag=self.dag)
  File "/opt/anaconda3/lib/python3.9/site-packages/airflow/cli/cli_parser.py", line 48, in command
    return func(*args, **kwargs)
  File "/opt/anaconda3/lib/python3.9/site-packages/airflow/utils/cli.py", line 92, in wrapper
    return f(*args, **kwargs)
  File "/opt/anaconda3/lib/python3.9/site-packages/airflow/cli/commands/task_command.py", line 298, in task_run
    _run_task_by_selected_method(args, dag, ti)
  File "/opt/anaconda3/lib/python3.9/site-packages/airflow/cli/commands/task_command.py", line 107, in _run_task_by_selected_method
    _run_raw_task(args, ti)
  File "/opt/anaconda3/lib/python3.9/site-packages/airflow/cli/commands/task_command.py", line 180, in _run_raw_task
    ti._run_raw_task(
  File "/opt/anaconda3/lib/python3.9/site-packages/airflow/utils/session.py", line 70, in wrapper
    return func(*args, session=session, **kwargs)
  File "/opt/anaconda3/lib/python3.9/site-packages/airflow/models/taskinstance.py", line 1334, in _run_raw_task
    self._execute_task_with_callbacks(context)
  File "/opt/anaconda3/lib/python3.9/site-packages/airflow/models/taskinstance.py", line 1460, in _execute_task_with_callbacks
    result = self._execute_task(context, self.task)
  File "/opt/anaconda3/lib/python3.9/site-packages/airflow/models/taskinstance.py", line 1516, in _execute_task
    result = execute_callable(context=context)
  File "/opt/anaconda3/lib/python3.9/site-packages/airflow/operators/python.py", line 174, in execute
    return_value = self.execute_callable()
  File "/opt/anaconda3/lib/python3.9/site-packages/airflow/operators/python.py", line 188, in execute_callable
    return self.python_callable(*self.op_args, **self.op_kwargs)
  File "/Users/HomeFolder/airflow/dags/simple_dag.py", line 19, in request_user
    json.dump(json_data, json_file)
NameError: name 'json' is not defined
[2022-03-14 12:15:07,622] {local_task_job.py:154} INFO - Task exited with return code 1
[2022-03-14 12:15:07,642] {local_task_job.py:264} INFO - 0 downstream tasks scheduled from follow-on schedule check
[2022-03-14 12:16:43,740] {taskinstance.py:1037} INFO - Dependencies all met for <TaskInstance: simple_dag.request_user scheduled__2022-03-14T12:18:00+00:00 [queued]>
[2022-03-14 12:16:43,747] {taskinstance.py:1037} INFO - Dependencies all met for <TaskInstance: simple_dag.request_user scheduled__2022-03-14T12:18:00+00:00 [queued]>
[2022-03-14 12:16:43,747] {taskinstance.py:1243} INFO - 
--------------------------------------------------------------------------------
[2022-03-14 12:16:43,747] {taskinstance.py:1244} INFO - Starting attempt 1 of 1
[2022-03-14 12:16:43,747] {taskinstance.py:1245} INFO - 
--------------------------------------------------------------------------------
[2022-03-14 12:16:43,756] {taskinstance.py:1264} INFO - Executing <Task(PythonOperator): request_user> on 2022-03-14 12:18:00+00:00
[2022-03-14 12:16:43,759] {standard_task_runner.py:52} INFO - Started process 83005 to run task
[2022-03-14 12:16:43,765] {standard_task_runner.py:76} INFO - Running: ['airflow', 'tasks', 'run', 'simple_dag', 'request_user', 'scheduled__2022-03-14T12:18:00+00:00', '--job-id', '156', '--raw', '--subdir', 'DAGS_FOLDER/simple_dag.py', '--cfg-path', '/var/folders/tl/ljh9dpdd2fnbgmc62qc2b49h0000gn/T/tmpwbq_4b4a', '--error-file', '/var/folders/tl/ljh9dpdd2fnbgmc62qc2b49h0000gn/T/tmpkmt5ll3_']
[2022-03-14 12:16:43,768] {standard_task_runner.py:77} INFO - Job 156: Subtask request_user
[2022-03-14 12:16:43,828] {logging_mixin.py:109} INFO - Running <TaskInstance: simple_dag.request_user scheduled__2022-03-14T12:18:00+00:00 [running]> on host 1.0.0.0.0.0.0.0.0.0.0.0.0.0.0.0.0.0.0.0.0.0.0.0.0.0.0.0.0.0.0.0.ip6.arpa
[2022-03-14 12:16:43,881] {taskinstance.py:1429} INFO - Exporting the following env vars:
AIRFLOW_CTX_DAG_OWNER=airflow
AIRFLOW_CTX_DAG_ID=simple_dag
AIRFLOW_CTX_TASK_ID=request_user
AIRFLOW_CTX_EXECUTION_DATE=2022-03-14T12:18:00+00:00
AIRFLOW_CTX_DAG_RUN_ID=scheduled__2022-03-14T12:18:00+00:00
[2022-03-14 12:16:46,010] {python.py:175} INFO - Done. Returned value was: None
[2022-03-14 12:16:46,020] {taskinstance.py:1272} INFO - Marking task as SUCCESS. dag_id=simple_dag, task_id=request_user, execution_date=20220314T121800, start_date=20220314T171643, end_date=20220314T171646
[2022-03-14 12:16:46,071] {local_task_job.py:154} INFO - Task exited with return code 0
[2022-03-14 12:16:46,090] {local_task_job.py:264} INFO - 0 downstream tasks scheduled from follow-on schedule check
