[2022-03-15 14:43:31,105] {taskinstance.py:1037} INFO - Dependencies all met for <TaskInstance: simple_dag.s3_sensor scheduled__2022-03-15T14:42:10.746723+00:00 [queued]>
[2022-03-15 14:43:31,115] {taskinstance.py:1037} INFO - Dependencies all met for <TaskInstance: simple_dag.s3_sensor scheduled__2022-03-15T14:42:10.746723+00:00 [queued]>
[2022-03-15 14:43:31,115] {taskinstance.py:1243} INFO - 
--------------------------------------------------------------------------------
[2022-03-15 14:43:31,115] {taskinstance.py:1244} INFO - Starting attempt 1 of 1
[2022-03-15 14:43:31,115] {taskinstance.py:1245} INFO - 
--------------------------------------------------------------------------------
[2022-03-15 14:43:31,124] {taskinstance.py:1264} INFO - Executing <Task(S3PrefixSensor): s3_sensor> on 2022-03-15 14:42:10.746723+00:00
[2022-03-15 14:43:31,128] {standard_task_runner.py:52} INFO - Started process 27115 to run task
[2022-03-15 14:43:31,135] {standard_task_runner.py:76} INFO - Running: ['airflow', 'tasks', 'run', 'simple_dag', 's3_sensor', 'scheduled__2022-03-15T14:42:10.746723+00:00', '--job-id', '333', '--raw', '--subdir', 'DAGS_FOLDER/simple_dag.py', '--cfg-path', '/var/folders/tl/ljh9dpdd2fnbgmc62qc2b49h0000gn/T/tmpp340xhtv', '--error-file', '/var/folders/tl/ljh9dpdd2fnbgmc62qc2b49h0000gn/T/tmph63ttvs1']
[2022-03-15 14:43:31,138] {standard_task_runner.py:77} INFO - Job 333: Subtask s3_sensor
[2022-03-15 14:43:31,195] {logging_mixin.py:109} INFO - Running <TaskInstance: simple_dag.s3_sensor scheduled__2022-03-15T14:42:10.746723+00:00 [running]> on host 1.0.0.0.0.0.0.0.0.0.0.0.0.0.0.0.0.0.0.0.0.0.0.0.0.0.0.0.0.0.0.0.ip6.arpa
[2022-03-15 14:43:31,243] {taskinstance.py:1429} INFO - Exporting the following env vars:
AIRFLOW_CTX_DAG_OWNER=airflow
AIRFLOW_CTX_DAG_ID=simple_dag
AIRFLOW_CTX_TASK_ID=s3_sensor
AIRFLOW_CTX_EXECUTION_DATE=2022-03-15T14:42:10.746723+00:00
AIRFLOW_CTX_DAG_RUN_ID=scheduled__2022-03-15T14:42:10.746723+00:00
[2022-03-15 14:43:31,245] {s3.py:390} INFO - Poking for prefix : ['raw/'] in bucket s3://airflowrs
[2022-03-15 14:43:31,252] {base_aws.py:190} INFO - Credentials retrieved from login
[2022-03-15 14:43:31,253] {base_aws.py:90} INFO - Retrieving region_name from Connection.extra_config['region_name']
[2022-03-15 14:44:31,645] {s3.py:390} INFO - Poking for prefix : ['raw/'] in bucket s3://airflowrs
[2022-03-15 14:44:54,621] {process_utils.py:120} INFO - Sending Signals.SIGTERM to group 27115. PIDs of all processes in the group: [27115]
[2022-03-15 14:44:54,627] {process_utils.py:75} INFO - Sending the signal Signals.SIGTERM to group 27115
[2022-03-15 14:44:54,627] {taskinstance.py:1413} ERROR - Received SIGTERM. Terminating subprocesses.
[2022-03-15 14:44:54,636] {taskinstance.py:1718} ERROR - Task failed with exception
Traceback (most recent call last):
  File "/opt/anaconda3/lib/python3.9/site-packages/airflow/models/taskinstance.py", line 1334, in _run_raw_task
    self._execute_task_with_callbacks(context)
  File "/opt/anaconda3/lib/python3.9/site-packages/airflow/models/taskinstance.py", line 1460, in _execute_task_with_callbacks
    result = self._execute_task(context, self.task)
  File "/opt/anaconda3/lib/python3.9/site-packages/airflow/models/taskinstance.py", line 1516, in _execute_task
    result = execute_callable(context=context)
  File "/opt/anaconda3/lib/python3.9/site-packages/airflow/sensors/base.py", line 249, in execute
    time.sleep(self._get_next_poke_interval(started_at, run_duration, try_number))
  File "/opt/anaconda3/lib/python3.9/site-packages/airflow/models/taskinstance.py", line 1415, in signal_handler
    raise AirflowException("Task received SIGTERM signal")
airflow.exceptions.AirflowException: Task received SIGTERM signal
[2022-03-15 14:44:54,649] {taskinstance.py:1272} INFO - Marking task as FAILED. dag_id=simple_dag, task_id=s3_sensor, execution_date=20220315T144210, start_date=20220315T194331, end_date=20220315T194454
[2022-03-15 14:44:54,661] {standard_task_runner.py:89} ERROR - Failed to execute job 333 for task s3_sensor
Traceback (most recent call last):
  File "/opt/anaconda3/lib/python3.9/site-packages/airflow/task/task_runner/standard_task_runner.py", line 85, in _start_by_fork
    args.func(args, dag=self.dag)
  File "/opt/anaconda3/lib/python3.9/site-packages/airflow/cli/cli_parser.py", line 48, in command
    return func(*args, **kwargs)
  File "/opt/anaconda3/lib/python3.9/site-packages/airflow/utils/cli.py", line 92, in wrapper
    return f(*args, **kwargs)
  File "/opt/anaconda3/lib/python3.9/site-packages/airflow/cli/commands/task_command.py", line 298, in task_run
    _run_task_by_selected_method(args, dag, ti)
  File "/opt/anaconda3/lib/python3.9/site-packages/airflow/cli/commands/task_command.py", line 107, in _run_task_by_selected_method
    _run_raw_task(args, ti)
  File "/opt/anaconda3/lib/python3.9/site-packages/airflow/cli/commands/task_command.py", line 180, in _run_raw_task
    ti._run_raw_task(
  File "/opt/anaconda3/lib/python3.9/site-packages/airflow/utils/session.py", line 70, in wrapper
    return func(*args, session=session, **kwargs)
  File "/opt/anaconda3/lib/python3.9/site-packages/airflow/models/taskinstance.py", line 1334, in _run_raw_task
    self._execute_task_with_callbacks(context)
  File "/opt/anaconda3/lib/python3.9/site-packages/airflow/models/taskinstance.py", line 1460, in _execute_task_with_callbacks
    result = self._execute_task(context, self.task)
  File "/opt/anaconda3/lib/python3.9/site-packages/airflow/models/taskinstance.py", line 1516, in _execute_task
    result = execute_callable(context=context)
  File "/opt/anaconda3/lib/python3.9/site-packages/airflow/sensors/base.py", line 249, in execute
    time.sleep(self._get_next_poke_interval(started_at, run_duration, try_number))
  File "/opt/anaconda3/lib/python3.9/site-packages/airflow/models/taskinstance.py", line 1415, in signal_handler
    raise AirflowException("Task received SIGTERM signal")
airflow.exceptions.AirflowException: Task received SIGTERM signal
[2022-03-15 14:44:54,684] {process_utils.py:70} INFO - Process psutil.Process(pid=27115, status='terminated', exitcode=1, started='14:43:31') (27115) terminated with exit code 1
