[2022-03-15 15:16:42,233] {taskinstance.py:1037} INFO - Dependencies all met for <TaskInstance: simple_dag.to_sql scheduled__2022-03-15T15:15:34.272779+00:00 [queued]>
[2022-03-15 15:16:42,239] {taskinstance.py:1037} INFO - Dependencies all met for <TaskInstance: simple_dag.to_sql scheduled__2022-03-15T15:15:34.272779+00:00 [queued]>
[2022-03-15 15:16:42,240] {taskinstance.py:1243} INFO - 
--------------------------------------------------------------------------------
[2022-03-15 15:16:42,240] {taskinstance.py:1244} INFO - Starting attempt 1 of 1
[2022-03-15 15:16:42,240] {taskinstance.py:1245} INFO - 
--------------------------------------------------------------------------------
[2022-03-15 15:16:42,249] {taskinstance.py:1264} INFO - Executing <Task(PythonOperator): to_sql> on 2022-03-15 15:15:34.272779+00:00
[2022-03-15 15:16:42,256] {standard_task_runner.py:52} INFO - Started process 28063 to run task
[2022-03-15 15:16:42,263] {standard_task_runner.py:76} INFO - Running: ['airflow', 'tasks', 'run', 'simple_dag', 'to_sql', 'scheduled__2022-03-15T15:15:34.272779+00:00', '--job-id', '341', '--raw', '--subdir', 'DAGS_FOLDER/simple_dag.py', '--cfg-path', '/var/folders/tl/ljh9dpdd2fnbgmc62qc2b49h0000gn/T/tmpkf4pyeh_', '--error-file', '/var/folders/tl/ljh9dpdd2fnbgmc62qc2b49h0000gn/T/tmpuqyq01dm']
[2022-03-15 15:16:42,272] {standard_task_runner.py:77} INFO - Job 341: Subtask to_sql
[2022-03-15 15:16:42,345] {logging_mixin.py:109} INFO - Running <TaskInstance: simple_dag.to_sql scheduled__2022-03-15T15:15:34.272779+00:00 [running]> on host 1.0.0.0.0.0.0.0.0.0.0.0.0.0.0.0.0.0.0.0.0.0.0.0.0.0.0.0.0.0.0.0.ip6.arpa
[2022-03-15 15:16:42,434] {taskinstance.py:1429} INFO - Exporting the following env vars:
AIRFLOW_CTX_DAG_OWNER=airflow
AIRFLOW_CTX_DAG_ID=simple_dag
AIRFLOW_CTX_TASK_ID=to_sql
AIRFLOW_CTX_EXECUTION_DATE=2022-03-15T15:15:34.272779+00:00
AIRFLOW_CTX_DAG_RUN_ID=scheduled__2022-03-15T15:15:34.272779+00:00
[2022-03-15 15:16:43,274] {logging_mixin.py:109} INFO - True
[2022-03-15 15:16:43,289] {base_aws.py:190} INFO - Credentials retrieved from login
[2022-03-15 15:16:43,290] {base_aws.py:90} INFO - Retrieving region_name from Connection.extra_config['region_name']
[2022-03-15 15:16:43,689] {base_aws.py:190} INFO - Credentials retrieved from login
[2022-03-15 15:16:43,690] {base_aws.py:90} INFO - Retrieving region_name from Connection.extra_config['region_name']
[2022-03-15 15:16:44,220] {base_aws.py:190} INFO - Credentials retrieved from login
[2022-03-15 15:16:44,221] {base_aws.py:90} INFO - Retrieving region_name from Connection.extra_config['region_name']
[2022-03-15 15:16:44,633] {base_aws.py:190} INFO - Credentials retrieved from login
[2022-03-15 15:16:44,635] {base_aws.py:90} INFO - Retrieving region_name from Connection.extra_config['region_name']
[2022-03-15 15:16:45,037] {base_aws.py:190} INFO - Credentials retrieved from login
[2022-03-15 15:16:45,038] {base_aws.py:90} INFO - Retrieving region_name from Connection.extra_config['region_name']
[2022-03-15 15:16:45,457] {base_aws.py:190} INFO - Credentials retrieved from login
[2022-03-15 15:16:45,459] {base_aws.py:90} INFO - Retrieving region_name from Connection.extra_config['region_name']
[2022-03-15 15:16:45,924] {base_aws.py:190} INFO - Credentials retrieved from login
[2022-03-15 15:16:45,925] {base_aws.py:90} INFO - Retrieving region_name from Connection.extra_config['region_name']
[2022-03-15 15:16:46,346] {base_aws.py:190} INFO - Credentials retrieved from login
[2022-03-15 15:16:46,347] {base_aws.py:90} INFO - Retrieving region_name from Connection.extra_config['region_name']
[2022-03-15 15:16:46,888] {base_aws.py:190} INFO - Credentials retrieved from login
[2022-03-15 15:16:46,889] {base_aws.py:90} INFO - Retrieving region_name from Connection.extra_config['region_name']
[2022-03-15 15:16:47,286] {base_aws.py:190} INFO - Credentials retrieved from login
[2022-03-15 15:16:47,289] {base_aws.py:90} INFO - Retrieving region_name from Connection.extra_config['region_name']
[2022-03-15 15:16:47,689] {base_aws.py:190} INFO - Credentials retrieved from login
[2022-03-15 15:16:47,690] {base_aws.py:90} INFO - Retrieving region_name from Connection.extra_config['region_name']
[2022-03-15 15:16:48,098] {base_aws.py:190} INFO - Credentials retrieved from login
[2022-03-15 15:16:48,099] {base_aws.py:90} INFO - Retrieving region_name from Connection.extra_config['region_name']
[2022-03-15 15:16:48,533] {base_aws.py:190} INFO - Credentials retrieved from login
[2022-03-15 15:16:48,534] {base_aws.py:90} INFO - Retrieving region_name from Connection.extra_config['region_name']
[2022-03-15 15:16:49,048] {base_aws.py:190} INFO - Credentials retrieved from login
[2022-03-15 15:16:49,049] {base_aws.py:90} INFO - Retrieving region_name from Connection.extra_config['region_name']
[2022-03-15 15:16:49,452] {base_aws.py:190} INFO - Credentials retrieved from login
[2022-03-15 15:16:49,453] {base_aws.py:90} INFO - Retrieving region_name from Connection.extra_config['region_name']
[2022-03-15 15:16:49,864] {base_aws.py:190} INFO - Credentials retrieved from login
[2022-03-15 15:16:49,865] {base_aws.py:90} INFO - Retrieving region_name from Connection.extra_config['region_name']
[2022-03-15 15:16:50,237] {base_aws.py:190} INFO - Credentials retrieved from login
[2022-03-15 15:16:50,238] {base_aws.py:90} INFO - Retrieving region_name from Connection.extra_config['region_name']
[2022-03-15 15:16:50,678] {base_aws.py:190} INFO - Credentials retrieved from login
[2022-03-15 15:16:50,679] {base_aws.py:90} INFO - Retrieving region_name from Connection.extra_config['region_name']
[2022-03-15 15:16:51,223] {base_aws.py:190} INFO - Credentials retrieved from login
[2022-03-15 15:16:51,224] {base_aws.py:90} INFO - Retrieving region_name from Connection.extra_config['region_name']
[2022-03-15 15:16:51,598] {base_aws.py:190} INFO - Credentials retrieved from login
[2022-03-15 15:16:51,599] {base_aws.py:90} INFO - Retrieving region_name from Connection.extra_config['region_name']
[2022-03-15 15:16:51,967] {taskinstance.py:1718} ERROR - Task failed with exception
Traceback (most recent call last):
  File "/opt/anaconda3/lib/python3.9/site-packages/airflow/models/taskinstance.py", line 1334, in _run_raw_task
    self._execute_task_with_callbacks(context)
  File "/opt/anaconda3/lib/python3.9/site-packages/airflow/models/taskinstance.py", line 1460, in _execute_task_with_callbacks
    result = self._execute_task(context, self.task)
  File "/opt/anaconda3/lib/python3.9/site-packages/airflow/models/taskinstance.py", line 1516, in _execute_task
    result = execute_callable(context=context)
  File "/opt/anaconda3/lib/python3.9/site-packages/airflow/operators/python.py", line 174, in execute
    return_value = self.execute_callable()
  File "/opt/anaconda3/lib/python3.9/site-packages/airflow/operators/python.py", line 188, in execute_callable
    return self.python_callable(*self.op_args, **self.op_kwargs)
  File "/Users/HomeFolder/airflow/dags/simple_dag.py", line 180, in to_sql
    print(pd.concat([pd.DataFrame(columns=columnsrecipe),recipelist]))
  File "/opt/anaconda3/lib/python3.9/site-packages/pandas/util/_decorators.py", line 311, in wrapper
    return func(*args, **kwargs)
  File "/opt/anaconda3/lib/python3.9/site-packages/pandas/core/reshape/concat.py", line 294, in concat
    op = _Concatenator(
  File "/opt/anaconda3/lib/python3.9/site-packages/pandas/core/reshape/concat.py", line 384, in __init__
    raise TypeError(msg)
TypeError: cannot concatenate object of type '<class 'list'>'; only Series and DataFrame objs are valid
[2022-03-15 15:16:51,982] {taskinstance.py:1272} INFO - Marking task as FAILED. dag_id=simple_dag, task_id=to_sql, execution_date=20220315T151534, start_date=20220315T201642, end_date=20220315T201651
[2022-03-15 15:16:51,995] {standard_task_runner.py:89} ERROR - Failed to execute job 341 for task to_sql
Traceback (most recent call last):
  File "/opt/anaconda3/lib/python3.9/site-packages/airflow/task/task_runner/standard_task_runner.py", line 85, in _start_by_fork
    args.func(args, dag=self.dag)
  File "/opt/anaconda3/lib/python3.9/site-packages/airflow/cli/cli_parser.py", line 48, in command
    return func(*args, **kwargs)
  File "/opt/anaconda3/lib/python3.9/site-packages/airflow/utils/cli.py", line 92, in wrapper
    return f(*args, **kwargs)
  File "/opt/anaconda3/lib/python3.9/site-packages/airflow/cli/commands/task_command.py", line 298, in task_run
    _run_task_by_selected_method(args, dag, ti)
  File "/opt/anaconda3/lib/python3.9/site-packages/airflow/cli/commands/task_command.py", line 107, in _run_task_by_selected_method
    _run_raw_task(args, ti)
  File "/opt/anaconda3/lib/python3.9/site-packages/airflow/cli/commands/task_command.py", line 180, in _run_raw_task
    ti._run_raw_task(
  File "/opt/anaconda3/lib/python3.9/site-packages/airflow/utils/session.py", line 70, in wrapper
    return func(*args, session=session, **kwargs)
  File "/opt/anaconda3/lib/python3.9/site-packages/airflow/models/taskinstance.py", line 1334, in _run_raw_task
    self._execute_task_with_callbacks(context)
  File "/opt/anaconda3/lib/python3.9/site-packages/airflow/models/taskinstance.py", line 1460, in _execute_task_with_callbacks
    result = self._execute_task(context, self.task)
  File "/opt/anaconda3/lib/python3.9/site-packages/airflow/models/taskinstance.py", line 1516, in _execute_task
    result = execute_callable(context=context)
  File "/opt/anaconda3/lib/python3.9/site-packages/airflow/operators/python.py", line 174, in execute
    return_value = self.execute_callable()
  File "/opt/anaconda3/lib/python3.9/site-packages/airflow/operators/python.py", line 188, in execute_callable
    return self.python_callable(*self.op_args, **self.op_kwargs)
  File "/Users/HomeFolder/airflow/dags/simple_dag.py", line 180, in to_sql
    print(pd.concat([pd.DataFrame(columns=columnsrecipe),recipelist]))
  File "/opt/anaconda3/lib/python3.9/site-packages/pandas/util/_decorators.py", line 311, in wrapper
    return func(*args, **kwargs)
  File "/opt/anaconda3/lib/python3.9/site-packages/pandas/core/reshape/concat.py", line 294, in concat
    op = _Concatenator(
  File "/opt/anaconda3/lib/python3.9/site-packages/pandas/core/reshape/concat.py", line 384, in __init__
    raise TypeError(msg)
TypeError: cannot concatenate object of type '<class 'list'>'; only Series and DataFrame objs are valid
[2022-03-15 15:16:52,056] {local_task_job.py:154} INFO - Task exited with return code 1
[2022-03-15 15:16:52,072] {local_task_job.py:264} INFO - 0 downstream tasks scheduled from follow-on schedule check
