[2022-03-14 13:25:40,941] {taskinstance.py:1037} INFO - Dependencies all met for <TaskInstance: simple_dag.upload_to_bucket scheduled__2022-03-14T13:26:00+00:00 [queued]>
[2022-03-14 13:25:40,949] {taskinstance.py:1037} INFO - Dependencies all met for <TaskInstance: simple_dag.upload_to_bucket scheduled__2022-03-14T13:26:00+00:00 [queued]>
[2022-03-14 13:25:40,949] {taskinstance.py:1243} INFO - 
--------------------------------------------------------------------------------
[2022-03-14 13:25:40,949] {taskinstance.py:1244} INFO - Starting attempt 1 of 1
[2022-03-14 13:25:40,949] {taskinstance.py:1245} INFO - 
--------------------------------------------------------------------------------
[2022-03-14 13:25:40,959] {taskinstance.py:1264} INFO - Executing <Task(PythonOperator): upload_to_bucket> on 2022-03-14 13:26:00+00:00
[2022-03-14 13:25:40,963] {standard_task_runner.py:52} INFO - Started process 84951 to run task
[2022-03-14 13:25:40,970] {standard_task_runner.py:76} INFO - Running: ['airflow', 'tasks', 'run', 'simple_dag', 'upload_to_bucket', 'scheduled__2022-03-14T13:26:00+00:00', '--job-id', '167', '--raw', '--subdir', 'DAGS_FOLDER/simple_dag.py', '--cfg-path', '/var/folders/tl/ljh9dpdd2fnbgmc62qc2b49h0000gn/T/tmpn_0e80bs', '--error-file', '/var/folders/tl/ljh9dpdd2fnbgmc62qc2b49h0000gn/T/tmpb39azdbr']
[2022-03-14 13:25:40,973] {standard_task_runner.py:77} INFO - Job 167: Subtask upload_to_bucket
[2022-03-14 13:25:41,040] {logging_mixin.py:109} INFO - Running <TaskInstance: simple_dag.upload_to_bucket scheduled__2022-03-14T13:26:00+00:00 [running]> on host 1.0.0.0.0.0.0.0.0.0.0.0.0.0.0.0.0.0.0.0.0.0.0.0.0.0.0.0.0.0.0.0.ip6.arpa
[2022-03-14 13:25:41,095] {taskinstance.py:1429} INFO - Exporting the following env vars:
AIRFLOW_CTX_DAG_OWNER=airflow
AIRFLOW_CTX_DAG_ID=simple_dag
AIRFLOW_CTX_TASK_ID=upload_to_bucket
AIRFLOW_CTX_EXECUTION_DATE=2022-03-14T13:26:00+00:00
AIRFLOW_CTX_DAG_RUN_ID=scheduled__2022-03-14T13:26:00+00:00
[2022-03-14 13:25:41,099] {taskinstance.py:1718} ERROR - Task failed with exception
Traceback (most recent call last):
  File "/opt/anaconda3/lib/python3.9/site-packages/airflow/models/taskinstance.py", line 1334, in _run_raw_task
    self._execute_task_with_callbacks(context)
  File "/opt/anaconda3/lib/python3.9/site-packages/airflow/models/taskinstance.py", line 1460, in _execute_task_with_callbacks
    result = self._execute_task(context, self.task)
  File "/opt/anaconda3/lib/python3.9/site-packages/airflow/models/taskinstance.py", line 1516, in _execute_task
    result = execute_callable(context=context)
  File "/opt/anaconda3/lib/python3.9/site-packages/airflow/operators/python.py", line 174, in execute
    return_value = self.execute_callable()
  File "/opt/anaconda3/lib/python3.9/site-packages/airflow/operators/python.py", line 188, in execute_callable
    return self.python_callable(*self.op_args, **self.op_kwargs)
  File "/Users/HomeFolder/airflow/dags/simple_dag.py", line 26, in request_user
    key=''.join("raw/",file),
TypeError: str.join() takes exactly one argument (2 given)
[2022-03-14 13:25:41,110] {taskinstance.py:1272} INFO - Marking task as FAILED. dag_id=simple_dag, task_id=upload_to_bucket, execution_date=20220314T132600, start_date=20220314T182540, end_date=20220314T182541
[2022-03-14 13:25:41,125] {standard_task_runner.py:89} ERROR - Failed to execute job 167 for task upload_to_bucket
Traceback (most recent call last):
  File "/opt/anaconda3/lib/python3.9/site-packages/airflow/task/task_runner/standard_task_runner.py", line 85, in _start_by_fork
    args.func(args, dag=self.dag)
  File "/opt/anaconda3/lib/python3.9/site-packages/airflow/cli/cli_parser.py", line 48, in command
    return func(*args, **kwargs)
  File "/opt/anaconda3/lib/python3.9/site-packages/airflow/utils/cli.py", line 92, in wrapper
    return f(*args, **kwargs)
  File "/opt/anaconda3/lib/python3.9/site-packages/airflow/cli/commands/task_command.py", line 298, in task_run
    _run_task_by_selected_method(args, dag, ti)
  File "/opt/anaconda3/lib/python3.9/site-packages/airflow/cli/commands/task_command.py", line 107, in _run_task_by_selected_method
    _run_raw_task(args, ti)
  File "/opt/anaconda3/lib/python3.9/site-packages/airflow/cli/commands/task_command.py", line 180, in _run_raw_task
    ti._run_raw_task(
  File "/opt/anaconda3/lib/python3.9/site-packages/airflow/utils/session.py", line 70, in wrapper
    return func(*args, session=session, **kwargs)
  File "/opt/anaconda3/lib/python3.9/site-packages/airflow/models/taskinstance.py", line 1334, in _run_raw_task
    self._execute_task_with_callbacks(context)
  File "/opt/anaconda3/lib/python3.9/site-packages/airflow/models/taskinstance.py", line 1460, in _execute_task_with_callbacks
    result = self._execute_task(context, self.task)
  File "/opt/anaconda3/lib/python3.9/site-packages/airflow/models/taskinstance.py", line 1516, in _execute_task
    result = execute_callable(context=context)
  File "/opt/anaconda3/lib/python3.9/site-packages/airflow/operators/python.py", line 174, in execute
    return_value = self.execute_callable()
  File "/opt/anaconda3/lib/python3.9/site-packages/airflow/operators/python.py", line 188, in execute_callable
    return self.python_callable(*self.op_args, **self.op_kwargs)
  File "/Users/HomeFolder/airflow/dags/simple_dag.py", line 26, in request_user
    key=''.join("raw/",file),
TypeError: str.join() takes exactly one argument (2 given)
[2022-03-14 13:25:41,150] {local_task_job.py:154} INFO - Task exited with return code 1
[2022-03-14 13:25:41,210] {local_task_job.py:264} INFO - 0 downstream tasks scheduled from follow-on schedule check
[2022-03-14 13:25:41,228] {dagrun.py:530} ERROR - Marking run <DagRun simple_dag @ 2022-03-14 13:26:00+00:00: scheduled__2022-03-14T13:26:00+00:00, externally triggered: False> failed
[2022-03-14 13:25:41,228] {dagrun.py:590} INFO - DagRun Finished: dag_id=simple_dag, execution_date=2022-03-14 13:26:00+00:00, run_id=scheduled__2022-03-14T13:26:00+00:00, run_start_date=2022-03-14 18:25:32.572888+00:00, run_end_date=2022-03-14 18:25:41.228548+00:00, run_duration=8.65566, state=failed, external_trigger=False, run_type=scheduled, data_interval_start=2022-03-14 13:26:00+00:00, data_interval_end=2022-03-14 13:28:00+00:00, dag_hash=c2a1e8cf3586de285c5ccb761141fcbc
[2022-03-14 13:26:41,625] {taskinstance.py:1037} INFO - Dependencies all met for <TaskInstance: simple_dag.upload_to_bucket scheduled__2022-03-14T13:26:00+00:00 [queued]>
[2022-03-14 13:26:41,635] {taskinstance.py:1037} INFO - Dependencies all met for <TaskInstance: simple_dag.upload_to_bucket scheduled__2022-03-14T13:26:00+00:00 [queued]>
[2022-03-14 13:26:41,635] {taskinstance.py:1243} INFO - 
--------------------------------------------------------------------------------
[2022-03-14 13:26:41,635] {taskinstance.py:1244} INFO - Starting attempt 1 of 1
[2022-03-14 13:26:41,635] {taskinstance.py:1245} INFO - 
--------------------------------------------------------------------------------
[2022-03-14 13:26:41,648] {taskinstance.py:1264} INFO - Executing <Task(PythonOperator): upload_to_bucket> on 2022-03-14 13:26:00+00:00
[2022-03-14 13:26:41,652] {standard_task_runner.py:52} INFO - Started process 85013 to run task
[2022-03-14 13:26:41,660] {standard_task_runner.py:76} INFO - Running: ['airflow', 'tasks', 'run', 'simple_dag', 'upload_to_bucket', 'scheduled__2022-03-14T13:26:00+00:00', '--job-id', '168', '--raw', '--subdir', 'DAGS_FOLDER/simple_dag.py', '--cfg-path', '/var/folders/tl/ljh9dpdd2fnbgmc62qc2b49h0000gn/T/tmp8e0a0lzq', '--error-file', '/var/folders/tl/ljh9dpdd2fnbgmc62qc2b49h0000gn/T/tmpa_qsx1bf']
[2022-03-14 13:26:41,664] {standard_task_runner.py:77} INFO - Job 168: Subtask upload_to_bucket
[2022-03-14 13:26:41,723] {logging_mixin.py:109} INFO - Running <TaskInstance: simple_dag.upload_to_bucket scheduled__2022-03-14T13:26:00+00:00 [running]> on host 1.0.0.0.0.0.0.0.0.0.0.0.0.0.0.0.0.0.0.0.0.0.0.0.0.0.0.0.0.0.0.0.ip6.arpa
[2022-03-14 13:26:41,780] {taskinstance.py:1429} INFO - Exporting the following env vars:
AIRFLOW_CTX_DAG_OWNER=airflow
AIRFLOW_CTX_DAG_ID=simple_dag
AIRFLOW_CTX_TASK_ID=upload_to_bucket
AIRFLOW_CTX_EXECUTION_DATE=2022-03-14T13:26:00+00:00
AIRFLOW_CTX_DAG_RUN_ID=scheduled__2022-03-14T13:26:00+00:00
[2022-03-14 13:26:41,784] {taskinstance.py:1718} ERROR - Task failed with exception
Traceback (most recent call last):
  File "/opt/anaconda3/lib/python3.9/site-packages/airflow/models/taskinstance.py", line 1334, in _run_raw_task
    self._execute_task_with_callbacks(context)
  File "/opt/anaconda3/lib/python3.9/site-packages/airflow/models/taskinstance.py", line 1460, in _execute_task_with_callbacks
    result = self._execute_task(context, self.task)
  File "/opt/anaconda3/lib/python3.9/site-packages/airflow/models/taskinstance.py", line 1516, in _execute_task
    result = execute_callable(context=context)
  File "/opt/anaconda3/lib/python3.9/site-packages/airflow/operators/python.py", line 174, in execute
    return_value = self.execute_callable()
  File "/opt/anaconda3/lib/python3.9/site-packages/airflow/operators/python.py", line 188, in execute_callable
    return self.python_callable(*self.op_args, **self.op_kwargs)
  File "/Users/HomeFolder/airflow/dags/simple_dag.py", line 26, in request_user
    key=''.join("raw/",file),
TypeError: str.join() takes exactly one argument (2 given)
[2022-03-14 13:26:41,794] {taskinstance.py:1272} INFO - Marking task as FAILED. dag_id=simple_dag, task_id=upload_to_bucket, execution_date=20220314T132600, start_date=20220314T182641, end_date=20220314T182641
[2022-03-14 13:26:41,808] {standard_task_runner.py:89} ERROR - Failed to execute job 168 for task upload_to_bucket
Traceback (most recent call last):
  File "/opt/anaconda3/lib/python3.9/site-packages/airflow/task/task_runner/standard_task_runner.py", line 85, in _start_by_fork
    args.func(args, dag=self.dag)
  File "/opt/anaconda3/lib/python3.9/site-packages/airflow/cli/cli_parser.py", line 48, in command
    return func(*args, **kwargs)
  File "/opt/anaconda3/lib/python3.9/site-packages/airflow/utils/cli.py", line 92, in wrapper
    return f(*args, **kwargs)
  File "/opt/anaconda3/lib/python3.9/site-packages/airflow/cli/commands/task_command.py", line 298, in task_run
    _run_task_by_selected_method(args, dag, ti)
  File "/opt/anaconda3/lib/python3.9/site-packages/airflow/cli/commands/task_command.py", line 107, in _run_task_by_selected_method
    _run_raw_task(args, ti)
  File "/opt/anaconda3/lib/python3.9/site-packages/airflow/cli/commands/task_command.py", line 180, in _run_raw_task
    ti._run_raw_task(
  File "/opt/anaconda3/lib/python3.9/site-packages/airflow/utils/session.py", line 70, in wrapper
    return func(*args, session=session, **kwargs)
  File "/opt/anaconda3/lib/python3.9/site-packages/airflow/models/taskinstance.py", line 1334, in _run_raw_task
    self._execute_task_with_callbacks(context)
  File "/opt/anaconda3/lib/python3.9/site-packages/airflow/models/taskinstance.py", line 1460, in _execute_task_with_callbacks
    result = self._execute_task(context, self.task)
  File "/opt/anaconda3/lib/python3.9/site-packages/airflow/models/taskinstance.py", line 1516, in _execute_task
    result = execute_callable(context=context)
  File "/opt/anaconda3/lib/python3.9/site-packages/airflow/operators/python.py", line 174, in execute
    return_value = self.execute_callable()
  File "/opt/anaconda3/lib/python3.9/site-packages/airflow/operators/python.py", line 188, in execute_callable
    return self.python_callable(*self.op_args, **self.op_kwargs)
  File "/Users/HomeFolder/airflow/dags/simple_dag.py", line 26, in request_user
    key=''.join("raw/",file),
TypeError: str.join() takes exactly one argument (2 given)
[2022-03-14 13:26:41,839] {local_task_job.py:154} INFO - Task exited with return code 1
[2022-03-14 13:26:41,862] {local_task_job.py:264} INFO - 0 downstream tasks scheduled from follow-on schedule check
[2022-03-14 13:28:49,775] {taskinstance.py:1037} INFO - Dependencies all met for <TaskInstance: simple_dag.upload_to_bucket scheduled__2022-03-14T13:26:00+00:00 [queued]>
[2022-03-14 13:28:49,785] {taskinstance.py:1037} INFO - Dependencies all met for <TaskInstance: simple_dag.upload_to_bucket scheduled__2022-03-14T13:26:00+00:00 [queued]>
[2022-03-14 13:28:49,785] {taskinstance.py:1243} INFO - 
--------------------------------------------------------------------------------
[2022-03-14 13:28:49,785] {taskinstance.py:1244} INFO - Starting attempt 1 of 1
[2022-03-14 13:28:49,785] {taskinstance.py:1245} INFO - 
--------------------------------------------------------------------------------
[2022-03-14 13:28:49,794] {taskinstance.py:1264} INFO - Executing <Task(PythonOperator): upload_to_bucket> on 2022-03-14 13:26:00+00:00
[2022-03-14 13:28:49,798] {standard_task_runner.py:52} INFO - Started process 85156 to run task
[2022-03-14 13:28:49,805] {standard_task_runner.py:76} INFO - Running: ['airflow', 'tasks', 'run', 'simple_dag', 'upload_to_bucket', 'scheduled__2022-03-14T13:26:00+00:00', '--job-id', '168', '--raw', '--subdir', 'DAGS_FOLDER/simple_dag.py', '--cfg-path', '/var/folders/tl/ljh9dpdd2fnbgmc62qc2b49h0000gn/T/tmpgcqb2ikx', '--error-file', '/var/folders/tl/ljh9dpdd2fnbgmc62qc2b49h0000gn/T/tmpu3gtuyxm']
[2022-03-14 13:28:49,809] {standard_task_runner.py:77} INFO - Job 168: Subtask upload_to_bucket
[2022-03-14 13:28:49,871] {logging_mixin.py:109} INFO - Running <TaskInstance: simple_dag.upload_to_bucket scheduled__2022-03-14T13:26:00+00:00 [running]> on host 1.0.0.0.0.0.0.0.0.0.0.0.0.0.0.0.0.0.0.0.0.0.0.0.0.0.0.0.0.0.0.0.ip6.arpa
[2022-03-14 13:28:49,920] {taskinstance.py:1429} INFO - Exporting the following env vars:
AIRFLOW_CTX_DAG_OWNER=airflow
AIRFLOW_CTX_DAG_ID=simple_dag
AIRFLOW_CTX_TASK_ID=upload_to_bucket
AIRFLOW_CTX_EXECUTION_DATE=2022-03-14T13:26:00+00:00
AIRFLOW_CTX_DAG_RUN_ID=scheduled__2022-03-14T13:26:00+00:00
[2022-03-14 13:28:49,930] {base_aws.py:190} INFO - Credentials retrieved from login
[2022-03-14 13:28:49,931] {base_aws.py:90} INFO - Retrieving region_name from Connection.extra_config['region_name']
[2022-03-14 13:28:50,258] {taskinstance.py:1718} ERROR - Task failed with exception
Traceback (most recent call last):
  File "/opt/anaconda3/lib/python3.9/site-packages/airflow/models/taskinstance.py", line 1334, in _run_raw_task
    self._execute_task_with_callbacks(context)
  File "/opt/anaconda3/lib/python3.9/site-packages/airflow/models/taskinstance.py", line 1460, in _execute_task_with_callbacks
    result = self._execute_task(context, self.task)
  File "/opt/anaconda3/lib/python3.9/site-packages/airflow/models/taskinstance.py", line 1516, in _execute_task
    result = execute_callable(context=context)
  File "/opt/anaconda3/lib/python3.9/site-packages/airflow/operators/python.py", line 174, in execute
    return_value = self.execute_callable()
  File "/opt/anaconda3/lib/python3.9/site-packages/airflow/operators/python.py", line 188, in execute_callable
    return self.python_callable(*self.op_args, **self.op_kwargs)
  File "/Users/HomeFolder/airflow/dags/simple_dag.py", line 24, in request_user
    s3_hook.load_file(
  File "/opt/anaconda3/lib/python3.9/site-packages/airflow/providers/amazon/aws/hooks/s3.py", line 62, in wrapper
    return func(*bound_args.args, **bound_args.kwargs)
  File "/opt/anaconda3/lib/python3.9/site-packages/airflow/providers/amazon/aws/hooks/s3.py", line 90, in wrapper
    return func(*bound_args.args, **bound_args.kwargs)
  File "/opt/anaconda3/lib/python3.9/site-packages/airflow/providers/amazon/aws/hooks/s3.py", line 474, in load_file
    raise ValueError(f"The key {key} already exists.")
ValueError: The key raw/user-2022-03-14 12:16:52.065604.json already exists.
[2022-03-14 13:28:50,317] {taskinstance.py:1272} INFO - Marking task as FAILED. dag_id=simple_dag, task_id=upload_to_bucket, execution_date=20220314T132600, start_date=20220314T182849, end_date=20220314T182850
[2022-03-14 13:28:50,329] {standard_task_runner.py:89} ERROR - Failed to execute job 168 for task upload_to_bucket
Traceback (most recent call last):
  File "/opt/anaconda3/lib/python3.9/site-packages/airflow/task/task_runner/standard_task_runner.py", line 85, in _start_by_fork
    args.func(args, dag=self.dag)
  File "/opt/anaconda3/lib/python3.9/site-packages/airflow/cli/cli_parser.py", line 48, in command
    return func(*args, **kwargs)
  File "/opt/anaconda3/lib/python3.9/site-packages/airflow/utils/cli.py", line 92, in wrapper
    return f(*args, **kwargs)
  File "/opt/anaconda3/lib/python3.9/site-packages/airflow/cli/commands/task_command.py", line 298, in task_run
    _run_task_by_selected_method(args, dag, ti)
  File "/opt/anaconda3/lib/python3.9/site-packages/airflow/cli/commands/task_command.py", line 107, in _run_task_by_selected_method
    _run_raw_task(args, ti)
  File "/opt/anaconda3/lib/python3.9/site-packages/airflow/cli/commands/task_command.py", line 180, in _run_raw_task
    ti._run_raw_task(
  File "/opt/anaconda3/lib/python3.9/site-packages/airflow/utils/session.py", line 70, in wrapper
    return func(*args, session=session, **kwargs)
  File "/opt/anaconda3/lib/python3.9/site-packages/airflow/models/taskinstance.py", line 1334, in _run_raw_task
    self._execute_task_with_callbacks(context)
  File "/opt/anaconda3/lib/python3.9/site-packages/airflow/models/taskinstance.py", line 1460, in _execute_task_with_callbacks
    result = self._execute_task(context, self.task)
  File "/opt/anaconda3/lib/python3.9/site-packages/airflow/models/taskinstance.py", line 1516, in _execute_task
    result = execute_callable(context=context)
  File "/opt/anaconda3/lib/python3.9/site-packages/airflow/operators/python.py", line 174, in execute
    return_value = self.execute_callable()
  File "/opt/anaconda3/lib/python3.9/site-packages/airflow/operators/python.py", line 188, in execute_callable
    return self.python_callable(*self.op_args, **self.op_kwargs)
  File "/Users/HomeFolder/airflow/dags/simple_dag.py", line 24, in request_user
    s3_hook.load_file(
  File "/opt/anaconda3/lib/python3.9/site-packages/airflow/providers/amazon/aws/hooks/s3.py", line 62, in wrapper
    return func(*bound_args.args, **bound_args.kwargs)
  File "/opt/anaconda3/lib/python3.9/site-packages/airflow/providers/amazon/aws/hooks/s3.py", line 90, in wrapper
    return func(*bound_args.args, **bound_args.kwargs)
  File "/opt/anaconda3/lib/python3.9/site-packages/airflow/providers/amazon/aws/hooks/s3.py", line 474, in load_file
    raise ValueError(f"The key {key} already exists.")
ValueError: The key raw/user-2022-03-14 12:16:52.065604.json already exists.
[2022-03-14 13:28:50,374] {local_task_job.py:154} INFO - Task exited with return code 1
[2022-03-14 13:28:50,393] {local_task_job.py:264} INFO - 0 downstream tasks scheduled from follow-on schedule check
