[2022-03-14 13:25:37,867] {taskinstance.py:1037} INFO - Dependencies all met for <TaskInstance: simple_dag.upload_to_bucket scheduled__2022-03-14T13:24:00+00:00 [queued]>
[2022-03-14 13:25:37,874] {taskinstance.py:1037} INFO - Dependencies all met for <TaskInstance: simple_dag.upload_to_bucket scheduled__2022-03-14T13:24:00+00:00 [queued]>
[2022-03-14 13:25:37,874] {taskinstance.py:1243} INFO - 
--------------------------------------------------------------------------------
[2022-03-14 13:25:37,874] {taskinstance.py:1244} INFO - Starting attempt 1 of 1
[2022-03-14 13:25:37,874] {taskinstance.py:1245} INFO - 
--------------------------------------------------------------------------------
[2022-03-14 13:25:37,884] {taskinstance.py:1264} INFO - Executing <Task(PythonOperator): upload_to_bucket> on 2022-03-14 13:24:00+00:00
[2022-03-14 13:25:37,888] {standard_task_runner.py:52} INFO - Started process 84948 to run task
[2022-03-14 13:25:37,895] {standard_task_runner.py:76} INFO - Running: ['airflow', 'tasks', 'run', 'simple_dag', 'upload_to_bucket', 'scheduled__2022-03-14T13:24:00+00:00', '--job-id', '166', '--raw', '--subdir', 'DAGS_FOLDER/simple_dag.py', '--cfg-path', '/var/folders/tl/ljh9dpdd2fnbgmc62qc2b49h0000gn/T/tmpajb1aqat', '--error-file', '/var/folders/tl/ljh9dpdd2fnbgmc62qc2b49h0000gn/T/tmpy81j_rck']
[2022-03-14 13:25:37,898] {standard_task_runner.py:77} INFO - Job 166: Subtask upload_to_bucket
[2022-03-14 13:25:37,963] {logging_mixin.py:109} INFO - Running <TaskInstance: simple_dag.upload_to_bucket scheduled__2022-03-14T13:24:00+00:00 [running]> on host 1.0.0.0.0.0.0.0.0.0.0.0.0.0.0.0.0.0.0.0.0.0.0.0.0.0.0.0.0.0.0.0.ip6.arpa
[2022-03-14 13:25:38,017] {taskinstance.py:1429} INFO - Exporting the following env vars:
AIRFLOW_CTX_DAG_OWNER=airflow
AIRFLOW_CTX_DAG_ID=simple_dag
AIRFLOW_CTX_TASK_ID=upload_to_bucket
AIRFLOW_CTX_EXECUTION_DATE=2022-03-14T13:24:00+00:00
AIRFLOW_CTX_DAG_RUN_ID=scheduled__2022-03-14T13:24:00+00:00
[2022-03-14 13:25:38,020] {taskinstance.py:1718} ERROR - Task failed with exception
Traceback (most recent call last):
  File "/opt/anaconda3/lib/python3.9/site-packages/airflow/models/taskinstance.py", line 1334, in _run_raw_task
    self._execute_task_with_callbacks(context)
  File "/opt/anaconda3/lib/python3.9/site-packages/airflow/models/taskinstance.py", line 1460, in _execute_task_with_callbacks
    result = self._execute_task(context, self.task)
  File "/opt/anaconda3/lib/python3.9/site-packages/airflow/models/taskinstance.py", line 1516, in _execute_task
    result = execute_callable(context=context)
  File "/opt/anaconda3/lib/python3.9/site-packages/airflow/operators/python.py", line 174, in execute
    return_value = self.execute_callable()
  File "/opt/anaconda3/lib/python3.9/site-packages/airflow/operators/python.py", line 188, in execute_callable
    return self.python_callable(*self.op_args, **self.op_kwargs)
  File "/Users/HomeFolder/airflow/dags/simple_dag.py", line 26, in request_user
    key=''.join("raw/",file),
TypeError: str.join() takes exactly one argument (2 given)
[2022-03-14 13:25:38,069] {taskinstance.py:1272} INFO - Marking task as FAILED. dag_id=simple_dag, task_id=upload_to_bucket, execution_date=20220314T132400, start_date=20220314T182537, end_date=20220314T182538
[2022-03-14 13:25:38,083] {standard_task_runner.py:89} ERROR - Failed to execute job 166 for task upload_to_bucket
Traceback (most recent call last):
  File "/opt/anaconda3/lib/python3.9/site-packages/airflow/task/task_runner/standard_task_runner.py", line 85, in _start_by_fork
    args.func(args, dag=self.dag)
  File "/opt/anaconda3/lib/python3.9/site-packages/airflow/cli/cli_parser.py", line 48, in command
    return func(*args, **kwargs)
  File "/opt/anaconda3/lib/python3.9/site-packages/airflow/utils/cli.py", line 92, in wrapper
    return f(*args, **kwargs)
  File "/opt/anaconda3/lib/python3.9/site-packages/airflow/cli/commands/task_command.py", line 298, in task_run
    _run_task_by_selected_method(args, dag, ti)
  File "/opt/anaconda3/lib/python3.9/site-packages/airflow/cli/commands/task_command.py", line 107, in _run_task_by_selected_method
    _run_raw_task(args, ti)
  File "/opt/anaconda3/lib/python3.9/site-packages/airflow/cli/commands/task_command.py", line 180, in _run_raw_task
    ti._run_raw_task(
  File "/opt/anaconda3/lib/python3.9/site-packages/airflow/utils/session.py", line 70, in wrapper
    return func(*args, session=session, **kwargs)
  File "/opt/anaconda3/lib/python3.9/site-packages/airflow/models/taskinstance.py", line 1334, in _run_raw_task
    self._execute_task_with_callbacks(context)
  File "/opt/anaconda3/lib/python3.9/site-packages/airflow/models/taskinstance.py", line 1460, in _execute_task_with_callbacks
    result = self._execute_task(context, self.task)
  File "/opt/anaconda3/lib/python3.9/site-packages/airflow/models/taskinstance.py", line 1516, in _execute_task
    result = execute_callable(context=context)
  File "/opt/anaconda3/lib/python3.9/site-packages/airflow/operators/python.py", line 174, in execute
    return_value = self.execute_callable()
  File "/opt/anaconda3/lib/python3.9/site-packages/airflow/operators/python.py", line 188, in execute_callable
    return self.python_callable(*self.op_args, **self.op_kwargs)
  File "/Users/HomeFolder/airflow/dags/simple_dag.py", line 26, in request_user
    key=''.join("raw/",file),
TypeError: str.join() takes exactly one argument (2 given)
[2022-03-14 13:25:38,120] {local_task_job.py:154} INFO - Task exited with return code 1
[2022-03-14 13:25:38,149] {local_task_job.py:264} INFO - 0 downstream tasks scheduled from follow-on schedule check
[2022-03-14 13:26:38,339] {taskinstance.py:1037} INFO - Dependencies all met for <TaskInstance: simple_dag.upload_to_bucket scheduled__2022-03-14T13:24:00+00:00 [queued]>
[2022-03-14 13:26:38,349] {taskinstance.py:1037} INFO - Dependencies all met for <TaskInstance: simple_dag.upload_to_bucket scheduled__2022-03-14T13:24:00+00:00 [queued]>
[2022-03-14 13:26:38,349] {taskinstance.py:1243} INFO - 
--------------------------------------------------------------------------------
[2022-03-14 13:26:38,349] {taskinstance.py:1244} INFO - Starting attempt 1 of 1
[2022-03-14 13:26:38,349] {taskinstance.py:1245} INFO - 
--------------------------------------------------------------------------------
[2022-03-14 13:26:38,361] {taskinstance.py:1264} INFO - Executing <Task(PythonOperator): upload_to_bucket> on 2022-03-14 13:24:00+00:00
[2022-03-14 13:26:38,365] {standard_task_runner.py:52} INFO - Started process 85001 to run task
[2022-03-14 13:26:38,371] {standard_task_runner.py:76} INFO - Running: ['airflow', 'tasks', 'run', 'simple_dag', 'upload_to_bucket', 'scheduled__2022-03-14T13:24:00+00:00', '--job-id', '167', '--raw', '--subdir', 'DAGS_FOLDER/simple_dag.py', '--cfg-path', '/var/folders/tl/ljh9dpdd2fnbgmc62qc2b49h0000gn/T/tmpic2l1ezr', '--error-file', '/var/folders/tl/ljh9dpdd2fnbgmc62qc2b49h0000gn/T/tmp9k0ms6lx']
[2022-03-14 13:26:38,374] {standard_task_runner.py:77} INFO - Job 167: Subtask upload_to_bucket
[2022-03-14 13:26:38,434] {logging_mixin.py:109} INFO - Running <TaskInstance: simple_dag.upload_to_bucket scheduled__2022-03-14T13:24:00+00:00 [running]> on host 1.0.0.0.0.0.0.0.0.0.0.0.0.0.0.0.0.0.0.0.0.0.0.0.0.0.0.0.0.0.0.0.ip6.arpa
[2022-03-14 13:26:38,482] {taskinstance.py:1429} INFO - Exporting the following env vars:
AIRFLOW_CTX_DAG_OWNER=airflow
AIRFLOW_CTX_DAG_ID=simple_dag
AIRFLOW_CTX_TASK_ID=upload_to_bucket
AIRFLOW_CTX_EXECUTION_DATE=2022-03-14T13:24:00+00:00
AIRFLOW_CTX_DAG_RUN_ID=scheduled__2022-03-14T13:24:00+00:00
[2022-03-14 13:26:38,484] {taskinstance.py:1718} ERROR - Task failed with exception
Traceback (most recent call last):
  File "/opt/anaconda3/lib/python3.9/site-packages/airflow/models/taskinstance.py", line 1334, in _run_raw_task
    self._execute_task_with_callbacks(context)
  File "/opt/anaconda3/lib/python3.9/site-packages/airflow/models/taskinstance.py", line 1460, in _execute_task_with_callbacks
    result = self._execute_task(context, self.task)
  File "/opt/anaconda3/lib/python3.9/site-packages/airflow/models/taskinstance.py", line 1516, in _execute_task
    result = execute_callable(context=context)
  File "/opt/anaconda3/lib/python3.9/site-packages/airflow/operators/python.py", line 174, in execute
    return_value = self.execute_callable()
  File "/opt/anaconda3/lib/python3.9/site-packages/airflow/operators/python.py", line 188, in execute_callable
    return self.python_callable(*self.op_args, **self.op_kwargs)
  File "/Users/HomeFolder/airflow/dags/simple_dag.py", line 26, in request_user
    key=''.join("raw/",file),
TypeError: str.join() takes exactly one argument (2 given)
[2022-03-14 13:26:38,496] {taskinstance.py:1272} INFO - Marking task as FAILED. dag_id=simple_dag, task_id=upload_to_bucket, execution_date=20220314T132400, start_date=20220314T182638, end_date=20220314T182638
[2022-03-14 13:26:38,506] {standard_task_runner.py:89} ERROR - Failed to execute job 167 for task upload_to_bucket
Traceback (most recent call last):
  File "/opt/anaconda3/lib/python3.9/site-packages/airflow/task/task_runner/standard_task_runner.py", line 85, in _start_by_fork
    args.func(args, dag=self.dag)
  File "/opt/anaconda3/lib/python3.9/site-packages/airflow/cli/cli_parser.py", line 48, in command
    return func(*args, **kwargs)
  File "/opt/anaconda3/lib/python3.9/site-packages/airflow/utils/cli.py", line 92, in wrapper
    return f(*args, **kwargs)
  File "/opt/anaconda3/lib/python3.9/site-packages/airflow/cli/commands/task_command.py", line 298, in task_run
    _run_task_by_selected_method(args, dag, ti)
  File "/opt/anaconda3/lib/python3.9/site-packages/airflow/cli/commands/task_command.py", line 107, in _run_task_by_selected_method
    _run_raw_task(args, ti)
  File "/opt/anaconda3/lib/python3.9/site-packages/airflow/cli/commands/task_command.py", line 180, in _run_raw_task
    ti._run_raw_task(
  File "/opt/anaconda3/lib/python3.9/site-packages/airflow/utils/session.py", line 70, in wrapper
    return func(*args, session=session, **kwargs)
  File "/opt/anaconda3/lib/python3.9/site-packages/airflow/models/taskinstance.py", line 1334, in _run_raw_task
    self._execute_task_with_callbacks(context)
  File "/opt/anaconda3/lib/python3.9/site-packages/airflow/models/taskinstance.py", line 1460, in _execute_task_with_callbacks
    result = self._execute_task(context, self.task)
  File "/opt/anaconda3/lib/python3.9/site-packages/airflow/models/taskinstance.py", line 1516, in _execute_task
    result = execute_callable(context=context)
  File "/opt/anaconda3/lib/python3.9/site-packages/airflow/operators/python.py", line 174, in execute
    return_value = self.execute_callable()
  File "/opt/anaconda3/lib/python3.9/site-packages/airflow/operators/python.py", line 188, in execute_callable
    return self.python_callable(*self.op_args, **self.op_kwargs)
  File "/Users/HomeFolder/airflow/dags/simple_dag.py", line 26, in request_user
    key=''.join("raw/",file),
TypeError: str.join() takes exactly one argument (2 given)
[2022-03-14 13:26:38,549] {local_task_job.py:154} INFO - Task exited with return code 1
[2022-03-14 13:26:38,571] {local_task_job.py:264} INFO - 0 downstream tasks scheduled from follow-on schedule check
[2022-03-14 13:28:41,301] {taskinstance.py:1037} INFO - Dependencies all met for <TaskInstance: simple_dag.upload_to_bucket scheduled__2022-03-14T13:24:00+00:00 [queued]>
[2022-03-14 13:28:41,309] {taskinstance.py:1037} INFO - Dependencies all met for <TaskInstance: simple_dag.upload_to_bucket scheduled__2022-03-14T13:24:00+00:00 [queued]>
[2022-03-14 13:28:41,309] {taskinstance.py:1243} INFO - 
--------------------------------------------------------------------------------
[2022-03-14 13:28:41,309] {taskinstance.py:1244} INFO - Starting attempt 1 of 1
[2022-03-14 13:28:41,309] {taskinstance.py:1245} INFO - 
--------------------------------------------------------------------------------
[2022-03-14 13:28:41,319] {taskinstance.py:1264} INFO - Executing <Task(PythonOperator): upload_to_bucket> on 2022-03-14 13:24:00+00:00
[2022-03-14 13:28:41,322] {standard_task_runner.py:52} INFO - Started process 85149 to run task
[2022-03-14 13:28:41,328] {standard_task_runner.py:76} INFO - Running: ['airflow', 'tasks', 'run', 'simple_dag', 'upload_to_bucket', 'scheduled__2022-03-14T13:24:00+00:00', '--job-id', '166', '--raw', '--subdir', 'DAGS_FOLDER/simple_dag.py', '--cfg-path', '/var/folders/tl/ljh9dpdd2fnbgmc62qc2b49h0000gn/T/tmpst_o5_x4', '--error-file', '/var/folders/tl/ljh9dpdd2fnbgmc62qc2b49h0000gn/T/tmprig2ktmc']
[2022-03-14 13:28:41,331] {standard_task_runner.py:77} INFO - Job 166: Subtask upload_to_bucket
[2022-03-14 13:28:41,387] {logging_mixin.py:109} INFO - Running <TaskInstance: simple_dag.upload_to_bucket scheduled__2022-03-14T13:24:00+00:00 [running]> on host 1.0.0.0.0.0.0.0.0.0.0.0.0.0.0.0.0.0.0.0.0.0.0.0.0.0.0.0.0.0.0.0.ip6.arpa
[2022-03-14 13:28:41,435] {taskinstance.py:1429} INFO - Exporting the following env vars:
AIRFLOW_CTX_DAG_OWNER=airflow
AIRFLOW_CTX_DAG_ID=simple_dag
AIRFLOW_CTX_TASK_ID=upload_to_bucket
AIRFLOW_CTX_EXECUTION_DATE=2022-03-14T13:24:00+00:00
AIRFLOW_CTX_DAG_RUN_ID=scheduled__2022-03-14T13:24:00+00:00
[2022-03-14 13:28:41,443] {base_aws.py:190} INFO - Credentials retrieved from login
[2022-03-14 13:28:41,444] {base_aws.py:90} INFO - Retrieving region_name from Connection.extra_config['region_name']
[2022-03-14 13:28:43,893] {python.py:175} INFO - Done. Returned value was: None
[2022-03-14 13:28:43,902] {taskinstance.py:1272} INFO - Marking task as SUCCESS. dag_id=simple_dag, task_id=upload_to_bucket, execution_date=20220314T132400, start_date=20220314T182841, end_date=20220314T182843
[2022-03-14 13:28:43,962] {local_task_job.py:154} INFO - Task exited with return code 0
[2022-03-14 13:28:43,983] {local_task_job.py:264} INFO - 0 downstream tasks scheduled from follow-on schedule check
