[2022-03-14 12:15:35,530] {taskinstance.py:1037} INFO - Dependencies all met for <TaskInstance: simple_dag.request_user scheduled__2022-03-14T12:20:00+00:00 [queued]>
[2022-03-14 12:15:35,538] {taskinstance.py:1037} INFO - Dependencies all met for <TaskInstance: simple_dag.request_user scheduled__2022-03-14T12:20:00+00:00 [queued]>
[2022-03-14 12:15:35,538] {taskinstance.py:1243} INFO - 
--------------------------------------------------------------------------------
[2022-03-14 12:15:35,539] {taskinstance.py:1244} INFO - Starting attempt 1 of 1
[2022-03-14 12:15:35,539] {taskinstance.py:1245} INFO - 
--------------------------------------------------------------------------------
[2022-03-14 12:15:35,549] {taskinstance.py:1264} INFO - Executing <Task(PythonOperator): request_user> on 2022-03-14 12:20:00+00:00
[2022-03-14 12:15:35,552] {standard_task_runner.py:52} INFO - Started process 82944 to run task
[2022-03-14 12:15:35,559] {standard_task_runner.py:76} INFO - Running: ['airflow', 'tasks', 'run', 'simple_dag', 'request_user', 'scheduled__2022-03-14T12:20:00+00:00', '--job-id', '159', '--raw', '--subdir', 'DAGS_FOLDER/simple_dag.py', '--cfg-path', '/var/folders/tl/ljh9dpdd2fnbgmc62qc2b49h0000gn/T/tmpbk04wb4a', '--error-file', '/var/folders/tl/ljh9dpdd2fnbgmc62qc2b49h0000gn/T/tmp78apvfxi']
[2022-03-14 12:15:35,562] {standard_task_runner.py:77} INFO - Job 159: Subtask request_user
[2022-03-14 12:15:35,611] {logging_mixin.py:109} INFO - Running <TaskInstance: simple_dag.request_user scheduled__2022-03-14T12:20:00+00:00 [running]> on host 1.0.0.0.0.0.0.0.0.0.0.0.0.0.0.0.0.0.0.0.0.0.0.0.0.0.0.0.0.0.0.0.ip6.arpa
[2022-03-14 12:15:35,654] {taskinstance.py:1429} INFO - Exporting the following env vars:
AIRFLOW_CTX_DAG_OWNER=airflow
AIRFLOW_CTX_DAG_ID=simple_dag
AIRFLOW_CTX_TASK_ID=request_user
AIRFLOW_CTX_EXECUTION_DATE=2022-03-14T12:20:00+00:00
AIRFLOW_CTX_DAG_RUN_ID=scheduled__2022-03-14T12:20:00+00:00
[2022-03-14 12:15:35,773] {taskinstance.py:1718} ERROR - Task failed with exception
Traceback (most recent call last):
  File "/opt/anaconda3/lib/python3.9/site-packages/airflow/models/taskinstance.py", line 1334, in _run_raw_task
    self._execute_task_with_callbacks(context)
  File "/opt/anaconda3/lib/python3.9/site-packages/airflow/models/taskinstance.py", line 1460, in _execute_task_with_callbacks
    result = self._execute_task(context, self.task)
  File "/opt/anaconda3/lib/python3.9/site-packages/airflow/models/taskinstance.py", line 1516, in _execute_task
    result = execute_callable(context=context)
  File "/opt/anaconda3/lib/python3.9/site-packages/airflow/operators/python.py", line 174, in execute
    return_value = self.execute_callable()
  File "/opt/anaconda3/lib/python3.9/site-packages/airflow/operators/python.py", line 188, in execute_callable
    return self.python_callable(*self.op_args, **self.op_kwargs)
  File "/Users/HomeFolder/airflow/dags/simple_dag.py", line 19, in request_user
    json.dump(json_data, json_file)
NameError: name 'json' is not defined
[2022-03-14 12:15:35,782] {taskinstance.py:1272} INFO - Marking task as FAILED. dag_id=simple_dag, task_id=request_user, execution_date=20220314T122000, start_date=20220314T171535, end_date=20220314T171535
[2022-03-14 12:15:35,792] {standard_task_runner.py:89} ERROR - Failed to execute job 159 for task request_user
Traceback (most recent call last):
  File "/opt/anaconda3/lib/python3.9/site-packages/airflow/task/task_runner/standard_task_runner.py", line 85, in _start_by_fork
    args.func(args, dag=self.dag)
  File "/opt/anaconda3/lib/python3.9/site-packages/airflow/cli/cli_parser.py", line 48, in command
    return func(*args, **kwargs)
  File "/opt/anaconda3/lib/python3.9/site-packages/airflow/utils/cli.py", line 92, in wrapper
    return f(*args, **kwargs)
  File "/opt/anaconda3/lib/python3.9/site-packages/airflow/cli/commands/task_command.py", line 298, in task_run
    _run_task_by_selected_method(args, dag, ti)
  File "/opt/anaconda3/lib/python3.9/site-packages/airflow/cli/commands/task_command.py", line 107, in _run_task_by_selected_method
    _run_raw_task(args, ti)
  File "/opt/anaconda3/lib/python3.9/site-packages/airflow/cli/commands/task_command.py", line 180, in _run_raw_task
    ti._run_raw_task(
  File "/opt/anaconda3/lib/python3.9/site-packages/airflow/utils/session.py", line 70, in wrapper
    return func(*args, session=session, **kwargs)
  File "/opt/anaconda3/lib/python3.9/site-packages/airflow/models/taskinstance.py", line 1334, in _run_raw_task
    self._execute_task_with_callbacks(context)
  File "/opt/anaconda3/lib/python3.9/site-packages/airflow/models/taskinstance.py", line 1460, in _execute_task_with_callbacks
    result = self._execute_task(context, self.task)
  File "/opt/anaconda3/lib/python3.9/site-packages/airflow/models/taskinstance.py", line 1516, in _execute_task
    result = execute_callable(context=context)
  File "/opt/anaconda3/lib/python3.9/site-packages/airflow/operators/python.py", line 174, in execute
    return_value = self.execute_callable()
  File "/opt/anaconda3/lib/python3.9/site-packages/airflow/operators/python.py", line 188, in execute_callable
    return self.python_callable(*self.op_args, **self.op_kwargs)
  File "/Users/HomeFolder/airflow/dags/simple_dag.py", line 19, in request_user
    json.dump(json_data, json_file)
NameError: name 'json' is not defined
[2022-03-14 12:15:35,838] {local_task_job.py:154} INFO - Task exited with return code 1
[2022-03-14 12:15:35,859] {local_task_job.py:264} INFO - 0 downstream tasks scheduled from follow-on schedule check
[2022-03-14 12:16:51,223] {taskinstance.py:1037} INFO - Dependencies all met for <TaskInstance: simple_dag.request_user scheduled__2022-03-14T12:20:00+00:00 [queued]>
[2022-03-14 12:16:51,231] {taskinstance.py:1037} INFO - Dependencies all met for <TaskInstance: simple_dag.request_user scheduled__2022-03-14T12:20:00+00:00 [queued]>
[2022-03-14 12:16:51,231] {taskinstance.py:1243} INFO - 
--------------------------------------------------------------------------------
[2022-03-14 12:16:51,231] {taskinstance.py:1244} INFO - Starting attempt 1 of 1
[2022-03-14 12:16:51,231] {taskinstance.py:1245} INFO - 
--------------------------------------------------------------------------------
[2022-03-14 12:16:51,240] {taskinstance.py:1264} INFO - Executing <Task(PythonOperator): request_user> on 2022-03-14 12:20:00+00:00
[2022-03-14 12:16:51,244] {standard_task_runner.py:52} INFO - Started process 83011 to run task
[2022-03-14 12:16:51,250] {standard_task_runner.py:76} INFO - Running: ['airflow', 'tasks', 'run', 'simple_dag', 'request_user', 'scheduled__2022-03-14T12:20:00+00:00', '--job-id', '158', '--raw', '--subdir', 'DAGS_FOLDER/simple_dag.py', '--cfg-path', '/var/folders/tl/ljh9dpdd2fnbgmc62qc2b49h0000gn/T/tmpn4ccjmkj', '--error-file', '/var/folders/tl/ljh9dpdd2fnbgmc62qc2b49h0000gn/T/tmpjp6be8iw']
[2022-03-14 12:16:51,253] {standard_task_runner.py:77} INFO - Job 158: Subtask request_user
[2022-03-14 12:16:51,311] {logging_mixin.py:109} INFO - Running <TaskInstance: simple_dag.request_user scheduled__2022-03-14T12:20:00+00:00 [running]> on host 1.0.0.0.0.0.0.0.0.0.0.0.0.0.0.0.0.0.0.0.0.0.0.0.0.0.0.0.0.0.0.0.ip6.arpa
[2022-03-14 12:16:51,362] {taskinstance.py:1429} INFO - Exporting the following env vars:
AIRFLOW_CTX_DAG_OWNER=airflow
AIRFLOW_CTX_DAG_ID=simple_dag
AIRFLOW_CTX_TASK_ID=request_user
AIRFLOW_CTX_EXECUTION_DATE=2022-03-14T12:20:00+00:00
AIRFLOW_CTX_DAG_RUN_ID=scheduled__2022-03-14T12:20:00+00:00
[2022-03-14 12:16:54,068] {python.py:175} INFO - Done. Returned value was: None
[2022-03-14 12:16:54,077] {taskinstance.py:1272} INFO - Marking task as SUCCESS. dag_id=simple_dag, task_id=request_user, execution_date=20220314T122000, start_date=20220314T171651, end_date=20220314T171654
[2022-03-14 12:16:54,125] {local_task_job.py:154} INFO - Task exited with return code 0
[2022-03-14 12:16:54,143] {local_task_job.py:264} INFO - 0 downstream tasks scheduled from follow-on schedule check
