[2022-03-15 21:09:21,895] {taskinstance.py:1037} INFO - Dependencies all met for <TaskInstance: simple_dag.upload_to_bucket scheduled__2022-03-15T21:11:00+00:00 [queued]>
[2022-03-15 21:09:21,907] {taskinstance.py:1037} INFO - Dependencies all met for <TaskInstance: simple_dag.upload_to_bucket scheduled__2022-03-15T21:11:00+00:00 [queued]>
[2022-03-15 21:09:21,907] {taskinstance.py:1243} INFO - 
--------------------------------------------------------------------------------
[2022-03-15 21:09:21,907] {taskinstance.py:1244} INFO - Starting attempt 1 of 1
[2022-03-15 21:09:21,907] {taskinstance.py:1245} INFO - 
--------------------------------------------------------------------------------
[2022-03-15 21:09:21,918] {taskinstance.py:1264} INFO - Executing <Task(PythonOperator): upload_to_bucket> on 2022-03-15 21:11:00+00:00
[2022-03-15 21:09:21,923] {standard_task_runner.py:52} INFO - Started process 38884 to run task
[2022-03-15 21:09:21,931] {standard_task_runner.py:76} INFO - Running: ['airflow', 'tasks', 'run', 'simple_dag', 'upload_to_bucket', 'scheduled__2022-03-15T21:11:00+00:00', '--job-id', '404', '--raw', '--subdir', 'DAGS_FOLDER/simple_dag.py', '--cfg-path', '/var/folders/tl/ljh9dpdd2fnbgmc62qc2b49h0000gn/T/tmp2tau6o0p', '--error-file', '/var/folders/tl/ljh9dpdd2fnbgmc62qc2b49h0000gn/T/tmpyw0pjqw4']
[2022-03-15 21:09:21,934] {standard_task_runner.py:77} INFO - Job 404: Subtask upload_to_bucket
[2022-03-15 21:09:22,001] {logging_mixin.py:109} INFO - Running <TaskInstance: simple_dag.upload_to_bucket scheduled__2022-03-15T21:11:00+00:00 [running]> on host 1.0.0.0.0.0.0.0.0.0.0.0.0.0.0.0.0.0.0.0.0.0.0.0.0.0.0.0.0.0.0.0.ip6.arpa
[2022-03-15 21:09:22,062] {taskinstance.py:1429} INFO - Exporting the following env vars:
AIRFLOW_CTX_DAG_OWNER=airflow
AIRFLOW_CTX_DAG_ID=simple_dag
AIRFLOW_CTX_TASK_ID=upload_to_bucket
AIRFLOW_CTX_EXECUTION_DATE=2022-03-15T21:11:00+00:00
AIRFLOW_CTX_DAG_RUN_ID=scheduled__2022-03-15T21:11:00+00:00
[2022-03-15 21:10:20,078] {process_utils.py:120} INFO - Sending Signals.SIGTERM to group 38884. PIDs of all processes in the group: [38884]
[2022-03-15 21:10:20,084] {process_utils.py:75} INFO - Sending the signal Signals.SIGTERM to group 38884
[2022-03-15 21:10:20,084] {taskinstance.py:1413} ERROR - Received SIGTERM. Terminating subprocesses.
[2022-03-15 21:10:20,091] {taskinstance.py:1718} ERROR - Task failed with exception
Traceback (most recent call last):
  File "/opt/anaconda3/lib/python3.9/site-packages/airflow/models/taskinstance.py", line 1334, in _run_raw_task
    self._execute_task_with_callbacks(context)
  File "/opt/anaconda3/lib/python3.9/site-packages/airflow/models/taskinstance.py", line 1460, in _execute_task_with_callbacks
    result = self._execute_task(context, self.task)
  File "/opt/anaconda3/lib/python3.9/site-packages/airflow/models/taskinstance.py", line 1516, in _execute_task
    result = execute_callable(context=context)
  File "/opt/anaconda3/lib/python3.9/site-packages/airflow/operators/python.py", line 174, in execute
    return_value = self.execute_callable()
  File "/opt/anaconda3/lib/python3.9/site-packages/airflow/operators/python.py", line 188, in execute_callable
    return self.python_callable(*self.op_args, **self.op_kwargs)
  File "/Users/HomeFolder/airflow/dags/simple_dag.py", line 73, in upload_to_bucket
    data = json.load(f)
  File "/opt/anaconda3/lib/python3.9/json/__init__.py", line 293, in load
    return loads(fp.read(),
  File "/opt/anaconda3/lib/python3.9/codecs.py", line 319, in decode
    def decode(self, input, final=False):
  File "/opt/anaconda3/lib/python3.9/site-packages/airflow/models/taskinstance.py", line 1415, in signal_handler
    raise AirflowException("Task received SIGTERM signal")
airflow.exceptions.AirflowException: Task received SIGTERM signal
[2022-03-15 21:10:20,146] {taskinstance.py:1272} INFO - Marking task as FAILED. dag_id=simple_dag, task_id=upload_to_bucket, execution_date=20220315T211100, start_date=20220316T020921, end_date=20220316T021020
[2022-03-15 21:10:20,160] {standard_task_runner.py:89} ERROR - Failed to execute job 404 for task upload_to_bucket
Traceback (most recent call last):
  File "/opt/anaconda3/lib/python3.9/site-packages/airflow/task/task_runner/standard_task_runner.py", line 85, in _start_by_fork
    args.func(args, dag=self.dag)
  File "/opt/anaconda3/lib/python3.9/site-packages/airflow/cli/cli_parser.py", line 48, in command
    return func(*args, **kwargs)
  File "/opt/anaconda3/lib/python3.9/site-packages/airflow/utils/cli.py", line 92, in wrapper
    return f(*args, **kwargs)
  File "/opt/anaconda3/lib/python3.9/site-packages/airflow/cli/commands/task_command.py", line 298, in task_run
    _run_task_by_selected_method(args, dag, ti)
  File "/opt/anaconda3/lib/python3.9/site-packages/airflow/cli/commands/task_command.py", line 107, in _run_task_by_selected_method
    _run_raw_task(args, ti)
  File "/opt/anaconda3/lib/python3.9/site-packages/airflow/cli/commands/task_command.py", line 180, in _run_raw_task
    ti._run_raw_task(
  File "/opt/anaconda3/lib/python3.9/site-packages/airflow/utils/session.py", line 70, in wrapper
    return func(*args, session=session, **kwargs)
  File "/opt/anaconda3/lib/python3.9/site-packages/airflow/models/taskinstance.py", line 1334, in _run_raw_task
    self._execute_task_with_callbacks(context)
  File "/opt/anaconda3/lib/python3.9/site-packages/airflow/models/taskinstance.py", line 1460, in _execute_task_with_callbacks
    result = self._execute_task(context, self.task)
  File "/opt/anaconda3/lib/python3.9/site-packages/airflow/models/taskinstance.py", line 1516, in _execute_task
    result = execute_callable(context=context)
  File "/opt/anaconda3/lib/python3.9/site-packages/airflow/operators/python.py", line 174, in execute
    return_value = self.execute_callable()
  File "/opt/anaconda3/lib/python3.9/site-packages/airflow/operators/python.py", line 188, in execute_callable
    return self.python_callable(*self.op_args, **self.op_kwargs)
  File "/Users/HomeFolder/airflow/dags/simple_dag.py", line 73, in upload_to_bucket
    data = json.load(f)
  File "/opt/anaconda3/lib/python3.9/json/__init__.py", line 293, in load
    return loads(fp.read(),
  File "/opt/anaconda3/lib/python3.9/codecs.py", line 319, in decode
    def decode(self, input, final=False):
  File "/opt/anaconda3/lib/python3.9/site-packages/airflow/models/taskinstance.py", line 1415, in signal_handler
    raise AirflowException("Task received SIGTERM signal")
airflow.exceptions.AirflowException: Task received SIGTERM signal
[2022-03-15 21:10:20,185] {process_utils.py:70} INFO - Process psutil.Process(pid=38884, status='terminated', exitcode=1, started='21:09:21') (38884) terminated with exit code 1
[2022-03-15 21:12:02,305] {taskinstance.py:1037} INFO - Dependencies all met for <TaskInstance: simple_dag.upload_to_bucket scheduled__2022-03-15T21:11:00+00:00 [queued]>
[2022-03-15 21:12:02,314] {taskinstance.py:1037} INFO - Dependencies all met for <TaskInstance: simple_dag.upload_to_bucket scheduled__2022-03-15T21:11:00+00:00 [queued]>
[2022-03-15 21:12:02,314] {taskinstance.py:1243} INFO - 
--------------------------------------------------------------------------------
[2022-03-15 21:12:02,314] {taskinstance.py:1244} INFO - Starting attempt 1 of 1
[2022-03-15 21:12:02,314] {taskinstance.py:1245} INFO - 
--------------------------------------------------------------------------------
[2022-03-15 21:12:02,323] {taskinstance.py:1264} INFO - Executing <Task(PythonOperator): upload_to_bucket> on 2022-03-15 21:11:00+00:00
[2022-03-15 21:12:02,329] {standard_task_runner.py:52} INFO - Started process 38938 to run task
[2022-03-15 21:12:02,336] {standard_task_runner.py:76} INFO - Running: ['airflow', 'tasks', 'run', 'simple_dag', 'upload_to_bucket', 'scheduled__2022-03-15T21:11:00+00:00', '--job-id', '404', '--raw', '--subdir', 'DAGS_FOLDER/simple_dag.py', '--cfg-path', '/var/folders/tl/ljh9dpdd2fnbgmc62qc2b49h0000gn/T/tmppd40wdf1', '--error-file', '/var/folders/tl/ljh9dpdd2fnbgmc62qc2b49h0000gn/T/tmpotu0mmtw']
[2022-03-15 21:12:02,339] {standard_task_runner.py:77} INFO - Job 404: Subtask upload_to_bucket
[2022-03-15 21:12:02,402] {logging_mixin.py:109} INFO - Running <TaskInstance: simple_dag.upload_to_bucket scheduled__2022-03-15T21:11:00+00:00 [running]> on host 1.0.0.0.0.0.0.0.0.0.0.0.0.0.0.0.0.0.0.0.0.0.0.0.0.0.0.0.0.0.0.0.ip6.arpa
[2022-03-15 21:12:02,458] {taskinstance.py:1429} INFO - Exporting the following env vars:
AIRFLOW_CTX_DAG_OWNER=airflow
AIRFLOW_CTX_DAG_ID=simple_dag
AIRFLOW_CTX_TASK_ID=upload_to_bucket
AIRFLOW_CTX_EXECUTION_DATE=2022-03-15T21:11:00+00:00
AIRFLOW_CTX_DAG_RUN_ID=scheduled__2022-03-15T21:11:00+00:00
[2022-03-15 21:12:02,471] {base_aws.py:190} INFO - Credentials retrieved from login
[2022-03-15 21:12:02,472] {base_aws.py:90} INFO - Retrieving region_name from Connection.extra_config['region_name']
[2022-03-15 21:12:06,046] {python.py:175} INFO - Done. Returned value was: None
[2022-03-15 21:12:06,071] {taskinstance.py:1272} INFO - Marking task as SUCCESS. dag_id=simple_dag, task_id=upload_to_bucket, execution_date=20220315T211100, start_date=20220316T021202, end_date=20220316T021206
[2022-03-15 21:12:06,140] {local_task_job.py:154} INFO - Task exited with return code 0
[2022-03-15 21:12:06,189] {local_task_job.py:264} INFO - 1 downstream tasks scheduled from follow-on schedule check
