[2022-03-14 14:05:31,459] {taskinstance.py:1037} INFO - Dependencies all met for <TaskInstance: simple_dag.upload_to_bucket scheduled__2022-03-14T14:06:00+00:00 [queued]>
[2022-03-14 14:05:31,466] {taskinstance.py:1037} INFO - Dependencies all met for <TaskInstance: simple_dag.upload_to_bucket scheduled__2022-03-14T14:06:00+00:00 [queued]>
[2022-03-14 14:05:31,466] {taskinstance.py:1243} INFO - 
--------------------------------------------------------------------------------
[2022-03-14 14:05:31,467] {taskinstance.py:1244} INFO - Starting attempt 1 of 1
[2022-03-14 14:05:31,467] {taskinstance.py:1245} INFO - 
--------------------------------------------------------------------------------
[2022-03-14 14:05:31,476] {taskinstance.py:1264} INFO - Executing <Task(PythonOperator): upload_to_bucket> on 2022-03-14 14:06:00+00:00
[2022-03-14 14:05:31,480] {standard_task_runner.py:52} INFO - Started process 86958 to run task
[2022-03-14 14:05:31,487] {standard_task_runner.py:76} INFO - Running: ['airflow', 'tasks', 'run', 'simple_dag', 'upload_to_bucket', 'scheduled__2022-03-14T14:06:00+00:00', '--job-id', '181', '--raw', '--subdir', 'DAGS_FOLDER/simple_dag.py', '--cfg-path', '/var/folders/tl/ljh9dpdd2fnbgmc62qc2b49h0000gn/T/tmpo5ejnjbi', '--error-file', '/var/folders/tl/ljh9dpdd2fnbgmc62qc2b49h0000gn/T/tmp2i03r96j']
[2022-03-14 14:05:31,490] {standard_task_runner.py:77} INFO - Job 181: Subtask upload_to_bucket
[2022-03-14 14:05:31,552] {logging_mixin.py:109} INFO - Running <TaskInstance: simple_dag.upload_to_bucket scheduled__2022-03-14T14:06:00+00:00 [running]> on host 1.0.0.0.0.0.0.0.0.0.0.0.0.0.0.0.0.0.0.0.0.0.0.0.0.0.0.0.0.0.0.0.ip6.arpa
[2022-03-14 14:05:31,608] {taskinstance.py:1429} INFO - Exporting the following env vars:
AIRFLOW_CTX_DAG_OWNER=airflow
AIRFLOW_CTX_DAG_ID=simple_dag
AIRFLOW_CTX_TASK_ID=upload_to_bucket
AIRFLOW_CTX_EXECUTION_DATE=2022-03-14T14:06:00+00:00
AIRFLOW_CTX_DAG_RUN_ID=scheduled__2022-03-14T14:06:00+00:00
[2022-03-14 14:05:31,613] {taskinstance.py:1718} ERROR - Task failed with exception
Traceback (most recent call last):
  File "/opt/anaconda3/lib/python3.9/site-packages/airflow/models/taskinstance.py", line 1334, in _run_raw_task
    self._execute_task_with_callbacks(context)
  File "/opt/anaconda3/lib/python3.9/site-packages/airflow/models/taskinstance.py", line 1460, in _execute_task_with_callbacks
    result = self._execute_task(context, self.task)
  File "/opt/anaconda3/lib/python3.9/site-packages/airflow/models/taskinstance.py", line 1516, in _execute_task
    result = execute_callable(context=context)
  File "/opt/anaconda3/lib/python3.9/site-packages/airflow/operators/python.py", line 174, in execute
    return_value = self.execute_callable()
  File "/opt/anaconda3/lib/python3.9/site-packages/airflow/operators/python.py", line 188, in execute_callable
    return self.python_callable(*self.op_args, **self.op_kwargs)
  File "/Users/HomeFolder/airflow/dags/simple_dag.py", line 28, in upload_to_bucket
    data = json.load(f)
  File "/opt/anaconda3/lib/python3.9/json/__init__.py", line 293, in load
    return loads(fp.read(),
  File "/opt/anaconda3/lib/python3.9/json/__init__.py", line 346, in loads
    return _default_decoder.decode(s)
  File "/opt/anaconda3/lib/python3.9/json/decoder.py", line 337, in decode
    obj, end = self.raw_decode(s, idx=_w(s, 0).end())
  File "/opt/anaconda3/lib/python3.9/json/decoder.py", line 355, in raw_decode
    raise JSONDecodeError("Expecting value", s, err.value) from None
json.decoder.JSONDecodeError: Expecting value: line 1 column 1 (char 0)
[2022-03-14 14:05:31,626] {taskinstance.py:1272} INFO - Marking task as FAILED. dag_id=simple_dag, task_id=upload_to_bucket, execution_date=20220314T140600, start_date=20220314T190531, end_date=20220314T190531
[2022-03-14 14:05:31,638] {standard_task_runner.py:89} ERROR - Failed to execute job 181 for task upload_to_bucket
Traceback (most recent call last):
  File "/opt/anaconda3/lib/python3.9/site-packages/airflow/task/task_runner/standard_task_runner.py", line 85, in _start_by_fork
    args.func(args, dag=self.dag)
  File "/opt/anaconda3/lib/python3.9/site-packages/airflow/cli/cli_parser.py", line 48, in command
    return func(*args, **kwargs)
  File "/opt/anaconda3/lib/python3.9/site-packages/airflow/utils/cli.py", line 92, in wrapper
    return f(*args, **kwargs)
  File "/opt/anaconda3/lib/python3.9/site-packages/airflow/cli/commands/task_command.py", line 298, in task_run
    _run_task_by_selected_method(args, dag, ti)
  File "/opt/anaconda3/lib/python3.9/site-packages/airflow/cli/commands/task_command.py", line 107, in _run_task_by_selected_method
    _run_raw_task(args, ti)
  File "/opt/anaconda3/lib/python3.9/site-packages/airflow/cli/commands/task_command.py", line 180, in _run_raw_task
    ti._run_raw_task(
  File "/opt/anaconda3/lib/python3.9/site-packages/airflow/utils/session.py", line 70, in wrapper
    return func(*args, session=session, **kwargs)
  File "/opt/anaconda3/lib/python3.9/site-packages/airflow/models/taskinstance.py", line 1334, in _run_raw_task
    self._execute_task_with_callbacks(context)
  File "/opt/anaconda3/lib/python3.9/site-packages/airflow/models/taskinstance.py", line 1460, in _execute_task_with_callbacks
    result = self._execute_task(context, self.task)
  File "/opt/anaconda3/lib/python3.9/site-packages/airflow/models/taskinstance.py", line 1516, in _execute_task
    result = execute_callable(context=context)
  File "/opt/anaconda3/lib/python3.9/site-packages/airflow/operators/python.py", line 174, in execute
    return_value = self.execute_callable()
  File "/opt/anaconda3/lib/python3.9/site-packages/airflow/operators/python.py", line 188, in execute_callable
    return self.python_callable(*self.op_args, **self.op_kwargs)
  File "/Users/HomeFolder/airflow/dags/simple_dag.py", line 28, in upload_to_bucket
    data = json.load(f)
  File "/opt/anaconda3/lib/python3.9/json/__init__.py", line 293, in load
    return loads(fp.read(),
  File "/opt/anaconda3/lib/python3.9/json/__init__.py", line 346, in loads
    return _default_decoder.decode(s)
  File "/opt/anaconda3/lib/python3.9/json/decoder.py", line 337, in decode
    obj, end = self.raw_decode(s, idx=_w(s, 0).end())
  File "/opt/anaconda3/lib/python3.9/json/decoder.py", line 355, in raw_decode
    raise JSONDecodeError("Expecting value", s, err.value) from None
json.decoder.JSONDecodeError: Expecting value: line 1 column 1 (char 0)
[2022-03-14 14:05:31,666] {local_task_job.py:154} INFO - Task exited with return code 1
[2022-03-14 14:05:31,687] {local_task_job.py:264} INFO - 0 downstream tasks scheduled from follow-on schedule check
[2022-03-14 14:07:17,738] {taskinstance.py:1037} INFO - Dependencies all met for <TaskInstance: simple_dag.upload_to_bucket scheduled__2022-03-14T14:06:00+00:00 [queued]>
[2022-03-14 14:07:17,747] {taskinstance.py:1037} INFO - Dependencies all met for <TaskInstance: simple_dag.upload_to_bucket scheduled__2022-03-14T14:06:00+00:00 [queued]>
[2022-03-14 14:07:17,747] {taskinstance.py:1243} INFO - 
--------------------------------------------------------------------------------
[2022-03-14 14:07:17,747] {taskinstance.py:1244} INFO - Starting attempt 1 of 1
[2022-03-14 14:07:17,747] {taskinstance.py:1245} INFO - 
--------------------------------------------------------------------------------
[2022-03-14 14:07:17,759] {taskinstance.py:1264} INFO - Executing <Task(PythonOperator): upload_to_bucket> on 2022-03-14 14:06:00+00:00
[2022-03-14 14:07:17,763] {standard_task_runner.py:52} INFO - Started process 87043 to run task
[2022-03-14 14:07:17,769] {standard_task_runner.py:76} INFO - Running: ['airflow', 'tasks', 'run', 'simple_dag', 'upload_to_bucket', 'scheduled__2022-03-14T14:06:00+00:00', '--job-id', '182', '--raw', '--subdir', 'DAGS_FOLDER/simple_dag.py', '--cfg-path', '/var/folders/tl/ljh9dpdd2fnbgmc62qc2b49h0000gn/T/tmpso2lr8n4', '--error-file', '/var/folders/tl/ljh9dpdd2fnbgmc62qc2b49h0000gn/T/tmp54rlgsog']
[2022-03-14 14:07:17,772] {standard_task_runner.py:77} INFO - Job 182: Subtask upload_to_bucket
[2022-03-14 14:07:17,828] {logging_mixin.py:109} INFO - Running <TaskInstance: simple_dag.upload_to_bucket scheduled__2022-03-14T14:06:00+00:00 [running]> on host 1.0.0.0.0.0.0.0.0.0.0.0.0.0.0.0.0.0.0.0.0.0.0.0.0.0.0.0.0.0.0.0.ip6.arpa
[2022-03-14 14:07:17,876] {taskinstance.py:1429} INFO - Exporting the following env vars:
AIRFLOW_CTX_DAG_OWNER=airflow
AIRFLOW_CTX_DAG_ID=simple_dag
AIRFLOW_CTX_TASK_ID=upload_to_bucket
AIRFLOW_CTX_EXECUTION_DATE=2022-03-14T14:06:00+00:00
AIRFLOW_CTX_DAG_RUN_ID=scheduled__2022-03-14T14:06:00+00:00
[2022-03-14 14:07:17,881] {taskinstance.py:1718} ERROR - Task failed with exception
Traceback (most recent call last):
  File "/opt/anaconda3/lib/python3.9/site-packages/airflow/models/taskinstance.py", line 1334, in _run_raw_task
    self._execute_task_with_callbacks(context)
  File "/opt/anaconda3/lib/python3.9/site-packages/airflow/models/taskinstance.py", line 1460, in _execute_task_with_callbacks
    result = self._execute_task(context, self.task)
  File "/opt/anaconda3/lib/python3.9/site-packages/airflow/models/taskinstance.py", line 1516, in _execute_task
    result = execute_callable(context=context)
  File "/opt/anaconda3/lib/python3.9/site-packages/airflow/operators/python.py", line 174, in execute
    return_value = self.execute_callable()
  File "/opt/anaconda3/lib/python3.9/site-packages/airflow/operators/python.py", line 188, in execute_callable
    return self.python_callable(*self.op_args, **self.op_kwargs)
  File "/Users/HomeFolder/airflow/dags/simple_dag.py", line 28, in upload_to_bucket
    data = json.load(f)
  File "/opt/anaconda3/lib/python3.9/json/__init__.py", line 293, in load
    return loads(fp.read(),
  File "/opt/anaconda3/lib/python3.9/json/__init__.py", line 346, in loads
    return _default_decoder.decode(s)
  File "/opt/anaconda3/lib/python3.9/json/decoder.py", line 337, in decode
    obj, end = self.raw_decode(s, idx=_w(s, 0).end())
  File "/opt/anaconda3/lib/python3.9/json/decoder.py", line 355, in raw_decode
    raise JSONDecodeError("Expecting value", s, err.value) from None
json.decoder.JSONDecodeError: Expecting value: line 1 column 1 (char 0)
[2022-03-14 14:07:17,892] {taskinstance.py:1272} INFO - Marking task as FAILED. dag_id=simple_dag, task_id=upload_to_bucket, execution_date=20220314T140600, start_date=20220314T190717, end_date=20220314T190717
[2022-03-14 14:07:17,904] {standard_task_runner.py:89} ERROR - Failed to execute job 182 for task upload_to_bucket
Traceback (most recent call last):
  File "/opt/anaconda3/lib/python3.9/site-packages/airflow/task/task_runner/standard_task_runner.py", line 85, in _start_by_fork
    args.func(args, dag=self.dag)
  File "/opt/anaconda3/lib/python3.9/site-packages/airflow/cli/cli_parser.py", line 48, in command
    return func(*args, **kwargs)
  File "/opt/anaconda3/lib/python3.9/site-packages/airflow/utils/cli.py", line 92, in wrapper
    return f(*args, **kwargs)
  File "/opt/anaconda3/lib/python3.9/site-packages/airflow/cli/commands/task_command.py", line 298, in task_run
    _run_task_by_selected_method(args, dag, ti)
  File "/opt/anaconda3/lib/python3.9/site-packages/airflow/cli/commands/task_command.py", line 107, in _run_task_by_selected_method
    _run_raw_task(args, ti)
  File "/opt/anaconda3/lib/python3.9/site-packages/airflow/cli/commands/task_command.py", line 180, in _run_raw_task
    ti._run_raw_task(
  File "/opt/anaconda3/lib/python3.9/site-packages/airflow/utils/session.py", line 70, in wrapper
    return func(*args, session=session, **kwargs)
  File "/opt/anaconda3/lib/python3.9/site-packages/airflow/models/taskinstance.py", line 1334, in _run_raw_task
    self._execute_task_with_callbacks(context)
  File "/opt/anaconda3/lib/python3.9/site-packages/airflow/models/taskinstance.py", line 1460, in _execute_task_with_callbacks
    result = self._execute_task(context, self.task)
  File "/opt/anaconda3/lib/python3.9/site-packages/airflow/models/taskinstance.py", line 1516, in _execute_task
    result = execute_callable(context=context)
  File "/opt/anaconda3/lib/python3.9/site-packages/airflow/operators/python.py", line 174, in execute
    return_value = self.execute_callable()
  File "/opt/anaconda3/lib/python3.9/site-packages/airflow/operators/python.py", line 188, in execute_callable
    return self.python_callable(*self.op_args, **self.op_kwargs)
  File "/Users/HomeFolder/airflow/dags/simple_dag.py", line 28, in upload_to_bucket
    data = json.load(f)
  File "/opt/anaconda3/lib/python3.9/json/__init__.py", line 293, in load
    return loads(fp.read(),
  File "/opt/anaconda3/lib/python3.9/json/__init__.py", line 346, in loads
    return _default_decoder.decode(s)
  File "/opt/anaconda3/lib/python3.9/json/decoder.py", line 337, in decode
    obj, end = self.raw_decode(s, idx=_w(s, 0).end())
  File "/opt/anaconda3/lib/python3.9/json/decoder.py", line 355, in raw_decode
    raise JSONDecodeError("Expecting value", s, err.value) from None
json.decoder.JSONDecodeError: Expecting value: line 1 column 1 (char 0)
[2022-03-14 14:07:17,949] {local_task_job.py:154} INFO - Task exited with return code 1
[2022-03-14 14:07:17,971] {local_task_job.py:264} INFO - 0 downstream tasks scheduled from follow-on schedule check
[2022-03-14 14:07:17,980] {dagrun.py:530} ERROR - Marking run <DagRun simple_dag @ 2022-03-14 14:06:00+00:00: scheduled__2022-03-14T14:06:00+00:00, externally triggered: False> failed
[2022-03-14 14:07:17,980] {dagrun.py:590} INFO - DagRun Finished: dag_id=simple_dag, execution_date=2022-03-14 14:06:00+00:00, run_id=scheduled__2022-03-14T14:06:00+00:00, run_start_date=2022-03-14 19:07:09.606360+00:00, run_end_date=2022-03-14 19:07:17.980567+00:00, run_duration=8.374207, state=failed, external_trigger=False, run_type=scheduled, data_interval_start=2022-03-14 14:06:00+00:00, data_interval_end=2022-03-14 14:08:00+00:00, dag_hash=02edb5bb10594cbc496ea2d2adfaea01
