[2022-03-15 20:23:28,801] {taskinstance.py:1037} INFO - Dependencies all met for <TaskInstance: simple_dag.to_sql scheduled__2022-03-15T20:21:38.011190+00:00 [queued]>
[2022-03-15 20:23:28,812] {taskinstance.py:1037} INFO - Dependencies all met for <TaskInstance: simple_dag.to_sql scheduled__2022-03-15T20:21:38.011190+00:00 [queued]>
[2022-03-15 20:23:28,812] {taskinstance.py:1243} INFO - 
--------------------------------------------------------------------------------
[2022-03-15 20:23:28,812] {taskinstance.py:1244} INFO - Starting attempt 1 of 1
[2022-03-15 20:23:28,813] {taskinstance.py:1245} INFO - 
--------------------------------------------------------------------------------
[2022-03-15 20:23:28,822] {taskinstance.py:1264} INFO - Executing <Task(PythonOperator): to_sql> on 2022-03-15 20:21:38.011190+00:00
[2022-03-15 20:23:28,827] {standard_task_runner.py:52} INFO - Started process 37419 to run task
[2022-03-15 20:23:28,834] {standard_task_runner.py:76} INFO - Running: ['airflow', 'tasks', 'run', 'simple_dag', 'to_sql', 'scheduled__2022-03-15T20:21:38.011190+00:00', '--job-id', '388', '--raw', '--subdir', 'DAGS_FOLDER/simple_dag.py', '--cfg-path', '/var/folders/tl/ljh9dpdd2fnbgmc62qc2b49h0000gn/T/tmpylkzunjd', '--error-file', '/var/folders/tl/ljh9dpdd2fnbgmc62qc2b49h0000gn/T/tmpht17hmvz']
[2022-03-15 20:23:28,838] {standard_task_runner.py:77} INFO - Job 388: Subtask to_sql
[2022-03-15 20:23:28,896] {logging_mixin.py:109} INFO - Running <TaskInstance: simple_dag.to_sql scheduled__2022-03-15T20:21:38.011190+00:00 [running]> on host 1.0.0.0.0.0.0.0.0.0.0.0.0.0.0.0.0.0.0.0.0.0.0.0.0.0.0.0.0.0.0.0.ip6.arpa
[2022-03-15 20:23:28,941] {taskinstance.py:1429} INFO - Exporting the following env vars:
AIRFLOW_CTX_DAG_OWNER=airflow
AIRFLOW_CTX_DAG_ID=simple_dag
AIRFLOW_CTX_TASK_ID=to_sql
AIRFLOW_CTX_EXECUTION_DATE=2022-03-15T20:21:38.011190+00:00
AIRFLOW_CTX_DAG_RUN_ID=scheduled__2022-03-15T20:21:38.011190+00:00
[2022-03-15 20:23:29,638] {base_aws.py:190} INFO - Credentials retrieved from login
[2022-03-15 20:23:29,639] {base_aws.py:90} INFO - Retrieving region_name from Connection.extra_config['region_name']
[2022-03-15 20:23:29,995] {base_aws.py:190} INFO - Credentials retrieved from login
[2022-03-15 20:23:29,996] {base_aws.py:90} INFO - Retrieving region_name from Connection.extra_config['region_name']
[2022-03-15 20:23:30,567] {taskinstance.py:1718} ERROR - Task failed with exception
Traceback (most recent call last):
  File "/opt/anaconda3/lib/python3.9/site-packages/airflow/models/taskinstance.py", line 1334, in _run_raw_task
    self._execute_task_with_callbacks(context)
  File "/opt/anaconda3/lib/python3.9/site-packages/airflow/models/taskinstance.py", line 1460, in _execute_task_with_callbacks
    result = self._execute_task(context, self.task)
  File "/opt/anaconda3/lib/python3.9/site-packages/airflow/models/taskinstance.py", line 1516, in _execute_task
    result = execute_callable(context=context)
  File "/opt/anaconda3/lib/python3.9/site-packages/airflow/operators/python.py", line 174, in execute
    return_value = self.execute_callable()
  File "/opt/anaconda3/lib/python3.9/site-packages/airflow/operators/python.py", line 188, in execute_callable
    return self.python_callable(*self.op_args, **self.op_kwargs)
  File "/Users/HomeFolder/airflow/dags/simple_dag.py", line 176, in to_sql
    recipes = pd.DataFrame(jsons).drop_duplicates(subset=['id'], keep='last')
  File "/opt/anaconda3/lib/python3.9/site-packages/pandas/util/_decorators.py", line 311, in wrapper
    return func(*args, **kwargs)
  File "/opt/anaconda3/lib/python3.9/site-packages/pandas/core/frame.py", line 6063, in drop_duplicates
    duplicated = self.duplicated(subset, keep=keep)
  File "/opt/anaconda3/lib/python3.9/site-packages/pandas/core/frame.py", line 6197, in duplicated
    raise KeyError(diff)
KeyError: Index(['id'], dtype='object')
[2022-03-15 20:23:30,623] {taskinstance.py:1272} INFO - Marking task as FAILED. dag_id=simple_dag, task_id=to_sql, execution_date=20220315T202138, start_date=20220316T012328, end_date=20220316T012330
[2022-03-15 20:23:30,637] {standard_task_runner.py:89} ERROR - Failed to execute job 388 for task to_sql
Traceback (most recent call last):
  File "/opt/anaconda3/lib/python3.9/site-packages/airflow/task/task_runner/standard_task_runner.py", line 85, in _start_by_fork
    args.func(args, dag=self.dag)
  File "/opt/anaconda3/lib/python3.9/site-packages/airflow/cli/cli_parser.py", line 48, in command
    return func(*args, **kwargs)
  File "/opt/anaconda3/lib/python3.9/site-packages/airflow/utils/cli.py", line 92, in wrapper
    return f(*args, **kwargs)
  File "/opt/anaconda3/lib/python3.9/site-packages/airflow/cli/commands/task_command.py", line 298, in task_run
    _run_task_by_selected_method(args, dag, ti)
  File "/opt/anaconda3/lib/python3.9/site-packages/airflow/cli/commands/task_command.py", line 107, in _run_task_by_selected_method
    _run_raw_task(args, ti)
  File "/opt/anaconda3/lib/python3.9/site-packages/airflow/cli/commands/task_command.py", line 180, in _run_raw_task
    ti._run_raw_task(
  File "/opt/anaconda3/lib/python3.9/site-packages/airflow/utils/session.py", line 70, in wrapper
    return func(*args, session=session, **kwargs)
  File "/opt/anaconda3/lib/python3.9/site-packages/airflow/models/taskinstance.py", line 1334, in _run_raw_task
    self._execute_task_with_callbacks(context)
  File "/opt/anaconda3/lib/python3.9/site-packages/airflow/models/taskinstance.py", line 1460, in _execute_task_with_callbacks
    result = self._execute_task(context, self.task)
  File "/opt/anaconda3/lib/python3.9/site-packages/airflow/models/taskinstance.py", line 1516, in _execute_task
    result = execute_callable(context=context)
  File "/opt/anaconda3/lib/python3.9/site-packages/airflow/operators/python.py", line 174, in execute
    return_value = self.execute_callable()
  File "/opt/anaconda3/lib/python3.9/site-packages/airflow/operators/python.py", line 188, in execute_callable
    return self.python_callable(*self.op_args, **self.op_kwargs)
  File "/Users/HomeFolder/airflow/dags/simple_dag.py", line 176, in to_sql
    recipes = pd.DataFrame(jsons).drop_duplicates(subset=['id'], keep='last')
  File "/opt/anaconda3/lib/python3.9/site-packages/pandas/util/_decorators.py", line 311, in wrapper
    return func(*args, **kwargs)
  File "/opt/anaconda3/lib/python3.9/site-packages/pandas/core/frame.py", line 6063, in drop_duplicates
    duplicated = self.duplicated(subset, keep=keep)
  File "/opt/anaconda3/lib/python3.9/site-packages/pandas/core/frame.py", line 6197, in duplicated
    raise KeyError(diff)
KeyError: Index(['id'], dtype='object')
[2022-03-15 20:23:30,672] {local_task_job.py:154} INFO - Task exited with return code 1
[2022-03-15 20:23:30,694] {local_task_job.py:264} INFO - 0 downstream tasks scheduled from follow-on schedule check
